2016-10-03 16:05:00,333 INFO: Config filename: app/config.py [in /home/huydq17/PycharmProjects/agentstats-api/app/app.py:105]
2016-10-03 16:05:00,345 INFO: App log folder: /home/huydq17/PycharmProjects/agentstats-api/logs [in /home/huydq17/PycharmProjects/agentstats-api/app/app.py:106]
2016-10-03 16:05:45,650 INFO: Config filename: app/config.py [in /home/huydq17/PycharmProjects/agentstats-api/app/app.py:105]
2016-10-03 16:05:45,650 INFO: App log folder: /home/huydq17/PycharmProjects/agentstats-api/logs [in /home/huydq17/PycharmProjects/agentstats-api/app/app.py:106]
2016-10-03 16:08:54,057 INFO: Config filename: app/config.py [in /home/huydq17/PycharmProjects/agentstats-api/app/app.py:109]
2016-10-03 16:08:54,057 INFO: App log folder: /home/huydq17/PycharmProjects/agentstats-api/logs [in /home/huydq17/PycharmProjects/agentstats-api/app/app.py:110]
2016-10-03 16:09:14,050 INFO: Config filename: app/config.py [in /home/huydq17/PycharmProjects/agentstats-api/app/app.py:109]
2016-10-03 16:09:14,052 INFO: App log folder: /home/huydq17/PycharmProjects/agentstats-api/logs [in /home/huydq17/PycharmProjects/agentstats-api/app/app.py:110]
2016-10-03 16:09:37,307 INFO: Config filename: app/config.py [in /home/huydq17/PycharmProjects/agentstats-api/app/app.py:109]
2016-10-03 16:09:37,308 INFO: App log folder: /home/huydq17/PycharmProjects/agentstats-api/logs [in /home/huydq17/PycharmProjects/agentstats-api/app/app.py:110]
2016-10-04 15:00:01,408 INFO: Config filename: app/config.py [in /home/huydq17/PycharmProjects/agentstats-api/app/app.py:105]
2016-10-04 15:00:01,516 INFO: App log folder: /home/huydq17/PycharmProjects/agentstats-api/logs [in /home/huydq17/PycharmProjects/agentstats-api/app/app.py:106]
2016-10-04 15:00:07,821 ERROR: HTTP_STATUS_CODE_405: {'message': 'Method Not Allowed.', 'code': 405} [in /home/huydq17/PycharmProjects/agentstats-api/app/exceptions.py:191]
Traceback (most recent call last):
  File "/usr/local/lib/python2.7/dist-packages/flask/app.py", line 1475, in full_dispatch_request
    rv = self.dispatch_request()
  File "/usr/local/lib/python2.7/dist-packages/flask/app.py", line 1453, in dispatch_request
    self.raise_routing_exception(req)
  File "/usr/local/lib/python2.7/dist-packages/flask/app.py", line 1436, in raise_routing_exception
    raise request.routing_exception
MethodNotAllowed: 405: Method Not Allowed
2016-10-04 15:01:38,306 INFO: Config filename: app/config.py [in /home/huydq17/PycharmProjects/agentstats-api/app/app.py:105]
2016-10-04 15:01:38,307 INFO: App log folder: /home/huydq17/PycharmProjects/agentstats-api/logs [in /home/huydq17/PycharmProjects/agentstats-api/app/app.py:106]
2016-10-04 15:01:41,594 ERROR: HTTP_STATUS_CODE_500: {'message': 'Internal Server Error.', 'code': 500} [in /home/huydq17/PycharmProjects/agentstats-api/app/exceptions.py:191]
Traceback (most recent call last):
  File "/usr/local/lib/python2.7/dist-packages/flask/app.py", line 1475, in full_dispatch_request
    rv = self.dispatch_request()
  File "/usr/local/lib/python2.7/dist-packages/flask/app.py", line 1461, in dispatch_request
    return self.view_functions[rule.endpoint](**req.view_args)
  File "/home/huydq17/PycharmProjects/agentstats-api/app/api/agent.py", line 109, in list_agents
    return jsonify(result)
  File "/usr/local/lib/python2.7/dist-packages/flask/json.py", line 238, in jsonify
    indent=indent),
  File "/usr/local/lib/python2.7/dist-packages/flask/json.py", line 126, in dumps
    rv = _json.dumps(obj, **kwargs)
  File "/usr/lib/python2.7/json/__init__.py", line 250, in dumps
    sort_keys=sort_keys, **kw).encode(obj)
  File "/usr/lib/python2.7/json/encoder.py", line 209, in encode
    chunks = list(chunks)
  File "/usr/lib/python2.7/json/encoder.py", line 434, in _iterencode
    for chunk in _iterencode_dict(o, _current_indent_level):
  File "/usr/lib/python2.7/json/encoder.py", line 408, in _iterencode_dict
    for chunk in chunks:
  File "/usr/lib/python2.7/json/encoder.py", line 332, in _iterencode_list
    for chunk in chunks:
  File "/usr/lib/python2.7/json/encoder.py", line 408, in _iterencode_dict
    for chunk in chunks:
  File "/usr/lib/python2.7/json/encoder.py", line 442, in _iterencode
    o = _default(o)
  File "/usr/local/lib/python2.7/dist-packages/flask/json.py", line 83, in default
    return _json.JSONEncoder.default(self, o)
  File "/usr/lib/python2.7/json/encoder.py", line 184, in default
    raise TypeError(repr(o) + " is not JSON serializable")
TypeError: ObjectId('57f2201e3da9da5300de8dfd') is not JSON serializable
2016-10-04 15:08:20,605 INFO: Config filename: app/config.py [in /home/huydq17/PycharmProjects/agentstats-api/app/app.py:105]
2016-10-04 15:08:20,606 INFO: App log folder: /home/huydq17/PycharmProjects/agentstats-api/logs [in /home/huydq17/PycharmProjects/agentstats-api/app/app.py:106]
2016-10-04 15:08:25,880 ERROR: HTTP_STATUS_CODE_500: {'message': 'Internal Server Error.', 'code': 500} [in /home/huydq17/PycharmProjects/agentstats-api/app/exceptions.py:191]
Traceback (most recent call last):
  File "/usr/local/lib/python2.7/dist-packages/flask/app.py", line 1475, in full_dispatch_request
    rv = self.dispatch_request()
  File "/usr/local/lib/python2.7/dist-packages/flask/app.py", line 1461, in dispatch_request
    return self.view_functions[rule.endpoint](**req.view_args)
  File "/home/huydq17/PycharmProjects/agentstats-api/app/api/agent.py", line 110, in list_agents
    return jsonify(result)
  File "/usr/local/lib/python2.7/dist-packages/flask/json.py", line 238, in jsonify
    indent=indent),
  File "/usr/local/lib/python2.7/dist-packages/flask/json.py", line 126, in dumps
    rv = _json.dumps(obj, **kwargs)
  File "/usr/lib/python2.7/json/__init__.py", line 250, in dumps
    sort_keys=sort_keys, **kw).encode(obj)
  File "/usr/lib/python2.7/json/encoder.py", line 209, in encode
    chunks = list(chunks)
  File "/usr/lib/python2.7/json/encoder.py", line 434, in _iterencode
    for chunk in _iterencode_dict(o, _current_indent_level):
  File "/usr/lib/python2.7/json/encoder.py", line 408, in _iterencode_dict
    for chunk in chunks:
  File "/usr/lib/python2.7/json/encoder.py", line 332, in _iterencode_list
    for chunk in chunks:
  File "/usr/lib/python2.7/json/encoder.py", line 408, in _iterencode_dict
    for chunk in chunks:
  File "/usr/lib/python2.7/json/encoder.py", line 442, in _iterencode
    o = _default(o)
  File "/usr/local/lib/python2.7/dist-packages/flask/json.py", line 83, in default
    return _json.JSONEncoder.default(self, o)
  File "/usr/lib/python2.7/json/encoder.py", line 184, in default
    raise TypeError(repr(o) + " is not JSON serializable")
TypeError: ObjectId('57f2201e3da9da5300de8dfd') is not JSON serializable
2016-10-04 15:09:14,063 ERROR: HTTP_STATUS_CODE_500: {'message': 'Internal Server Error.', 'code': 500} [in /home/huydq17/PycharmProjects/agentstats-api/app/exceptions.py:191]
Traceback (most recent call last):
  File "/usr/local/lib/python2.7/dist-packages/flask/app.py", line 1475, in full_dispatch_request
    rv = self.dispatch_request()
  File "/usr/local/lib/python2.7/dist-packages/flask/app.py", line 1461, in dispatch_request
    return self.view_functions[rule.endpoint](**req.view_args)
  File "/home/huydq17/PycharmProjects/agentstats-api/app/api/agent.py", line 110, in list_agents
    return jsonify(result)
  File "/usr/local/lib/python2.7/dist-packages/flask/json.py", line 238, in jsonify
    indent=indent),
  File "/usr/local/lib/python2.7/dist-packages/flask/json.py", line 126, in dumps
    rv = _json.dumps(obj, **kwargs)
  File "/usr/lib/python2.7/json/__init__.py", line 250, in dumps
    sort_keys=sort_keys, **kw).encode(obj)
  File "/usr/lib/python2.7/json/encoder.py", line 209, in encode
    chunks = list(chunks)
  File "/usr/lib/python2.7/json/encoder.py", line 434, in _iterencode
    for chunk in _iterencode_dict(o, _current_indent_level):
  File "/usr/lib/python2.7/json/encoder.py", line 408, in _iterencode_dict
    for chunk in chunks:
  File "/usr/lib/python2.7/json/encoder.py", line 332, in _iterencode_list
    for chunk in chunks:
  File "/usr/lib/python2.7/json/encoder.py", line 408, in _iterencode_dict
    for chunk in chunks:
  File "/usr/lib/python2.7/json/encoder.py", line 442, in _iterencode
    o = _default(o)
  File "/usr/local/lib/python2.7/dist-packages/flask/json.py", line 83, in default
    return _json.JSONEncoder.default(self, o)
  File "/usr/lib/python2.7/json/encoder.py", line 184, in default
    raise TypeError(repr(o) + " is not JSON serializable")
TypeError: ObjectId('57f2201e3da9da5300de8dfd') is not JSON serializable
2016-10-04 15:09:15,633 ERROR: HTTP_STATUS_CODE_500: {'message': 'Internal Server Error.', 'code': 500} [in /home/huydq17/PycharmProjects/agentstats-api/app/exceptions.py:191]
Traceback (most recent call last):
  File "/usr/local/lib/python2.7/dist-packages/flask/app.py", line 1475, in full_dispatch_request
    rv = self.dispatch_request()
  File "/usr/local/lib/python2.7/dist-packages/flask/app.py", line 1461, in dispatch_request
    return self.view_functions[rule.endpoint](**req.view_args)
  File "/home/huydq17/PycharmProjects/agentstats-api/app/api/agent.py", line 110, in list_agents
    return jsonify(result)
  File "/usr/local/lib/python2.7/dist-packages/flask/json.py", line 238, in jsonify
    indent=indent),
  File "/usr/local/lib/python2.7/dist-packages/flask/json.py", line 126, in dumps
    rv = _json.dumps(obj, **kwargs)
  File "/usr/lib/python2.7/json/__init__.py", line 250, in dumps
    sort_keys=sort_keys, **kw).encode(obj)
  File "/usr/lib/python2.7/json/encoder.py", line 209, in encode
    chunks = list(chunks)
  File "/usr/lib/python2.7/json/encoder.py", line 434, in _iterencode
    for chunk in _iterencode_dict(o, _current_indent_level):
  File "/usr/lib/python2.7/json/encoder.py", line 408, in _iterencode_dict
    for chunk in chunks:
  File "/usr/lib/python2.7/json/encoder.py", line 332, in _iterencode_list
    for chunk in chunks:
  File "/usr/lib/python2.7/json/encoder.py", line 408, in _iterencode_dict
    for chunk in chunks:
  File "/usr/lib/python2.7/json/encoder.py", line 442, in _iterencode
    o = _default(o)
  File "/usr/local/lib/python2.7/dist-packages/flask/json.py", line 83, in default
    return _json.JSONEncoder.default(self, o)
  File "/usr/lib/python2.7/json/encoder.py", line 184, in default
    raise TypeError(repr(o) + " is not JSON serializable")
TypeError: ObjectId('57f2201e3da9da5300de8dfd') is not JSON serializable
2016-10-04 15:09:23,656 INFO: Config filename: app/config.py [in /home/huydq17/PycharmProjects/agentstats-api/app/app.py:105]
2016-10-04 15:09:23,660 INFO: App log folder: /home/huydq17/PycharmProjects/agentstats-api/logs [in /home/huydq17/PycharmProjects/agentstats-api/app/app.py:106]
2016-10-04 15:44:34,093 INFO: Config filename: app/config.py [in /home/huydq17/PycharmProjects/agentstats-api/app/app.py:105]
2016-10-04 15:44:34,093 INFO: App log folder: /home/huydq17/PycharmProjects/agentstats-api/logs [in /home/huydq17/PycharmProjects/agentstats-api/app/app.py:106]
2016-10-04 15:44:36,254 DEBUG: {u'error': {u'message': u'Bearer token scope not valid.', u'code': 401}} [in /usr/local/lib/python2.7/dist-packages/flask_oauth2/resources/__init__.py:47]
2016-10-04 15:44:36,255 ERROR: HTTP_STATUS_CODE_401: {u'message': u'Bearer token scope not valid.', u'code': 401} [in /home/huydq17/PycharmProjects/agentstats-api/app/exceptions.py:191]
Traceback (most recent call last):
  File "/usr/local/lib/python2.7/dist-packages/flask/app.py", line 1475, in full_dispatch_request
    rv = self.dispatch_request()
  File "/usr/local/lib/python2.7/dist-packages/flask/app.py", line 1461, in dispatch_request
    return self.view_functions[rule.endpoint](**req.view_args)
  File "/usr/local/lib/python2.7/dist-packages/flask_oauth2/resources/__init__.py", line 49, in decorated
    return abort(code, content['error'])
  File "/usr/local/lib/python2.7/dist-packages/werkzeug/exceptions.py", line 605, in __call__
    raise self.mapping[code](*args, **kwargs)
Unauthorized: 401: Unauthorized
2016-10-04 15:44:43,440 DEBUG: {u'error': {u'message': u'Bearer token scope not valid.', u'code': 401}} [in /usr/local/lib/python2.7/dist-packages/flask_oauth2/resources/__init__.py:47]
2016-10-04 15:44:43,441 ERROR: HTTP_STATUS_CODE_401: {u'message': u'Bearer token scope not valid.', u'code': 401} [in /home/huydq17/PycharmProjects/agentstats-api/app/exceptions.py:191]
Traceback (most recent call last):
  File "/usr/local/lib/python2.7/dist-packages/flask/app.py", line 1475, in full_dispatch_request
    rv = self.dispatch_request()
  File "/usr/local/lib/python2.7/dist-packages/flask/app.py", line 1461, in dispatch_request
    return self.view_functions[rule.endpoint](**req.view_args)
  File "/usr/local/lib/python2.7/dist-packages/flask_oauth2/resources/__init__.py", line 49, in decorated
    return abort(code, content['error'])
  File "/usr/local/lib/python2.7/dist-packages/werkzeug/exceptions.py", line 605, in __call__
    raise self.mapping[code](*args, **kwargs)
Unauthorized: 401: Unauthorized
2016-10-04 15:44:46,273 DEBUG: {u'error': {u'message': u'Bearer token scope not valid.', u'code': 401}} [in /usr/local/lib/python2.7/dist-packages/flask_oauth2/resources/__init__.py:47]
2016-10-04 15:44:46,275 ERROR: HTTP_STATUS_CODE_401: {u'message': u'Bearer token scope not valid.', u'code': 401} [in /home/huydq17/PycharmProjects/agentstats-api/app/exceptions.py:191]
Traceback (most recent call last):
  File "/usr/local/lib/python2.7/dist-packages/flask/app.py", line 1475, in full_dispatch_request
    rv = self.dispatch_request()
  File "/usr/local/lib/python2.7/dist-packages/flask/app.py", line 1461, in dispatch_request
    return self.view_functions[rule.endpoint](**req.view_args)
  File "/usr/local/lib/python2.7/dist-packages/flask_oauth2/resources/__init__.py", line 49, in decorated
    return abort(code, content['error'])
  File "/usr/local/lib/python2.7/dist-packages/werkzeug/exceptions.py", line 605, in __call__
    raise self.mapping[code](*args, **kwargs)
Unauthorized: 401: Unauthorized
2016-10-04 15:52:58,325 INFO: Config filename: app/config.py [in /home/huydq17/PycharmProjects/agentstats-api/app/app.py:105]
2016-10-04 15:52:58,328 INFO: App log folder: /home/huydq17/PycharmProjects/agentstats-api/logs [in /home/huydq17/PycharmProjects/agentstats-api/app/app.py:106]
2016-10-04 15:53:02,572 INFO: Config filename: app/config.py [in /home/huydq17/PycharmProjects/agentstats-api/app/app.py:105]
2016-10-04 15:53:02,573 INFO: App log folder: /home/huydq17/PycharmProjects/agentstats-api/logs [in /home/huydq17/PycharmProjects/agentstats-api/app/app.py:106]
2016-10-04 17:04:13,570 INFO: Config filename: app/config.py [in /home/huydq17/PycharmProjects/agentstats-api/app/app.py:105]
2016-10-04 17:04:13,570 INFO: App log folder: /home/huydq17/PycharmProjects/agentstats-api/logs [in /home/huydq17/PycharmProjects/agentstats-api/app/app.py:106]
2016-10-04 17:21:39,945 INFO: Config filename: app/config.py [in /home/huydq17/PycharmProjects/agentstats-api/app/app.py:105]
2016-10-04 17:21:39,946 INFO: App log folder: /home/huydq17/PycharmProjects/agentstats-api/logs [in /home/huydq17/PycharmProjects/agentstats-api/app/app.py:106]
2016-10-04 17:24:51,950 INFO: Config filename: app/config.py [in /home/huydq17/PycharmProjects/agentstats-api/app/app.py:105]
2016-10-04 17:24:51,951 INFO: App log folder: /home/huydq17/PycharmProjects/agentstats-api/logs [in /home/huydq17/PycharmProjects/agentstats-api/app/app.py:106]
2016-10-04 17:28:23,713 INFO: Config filename: app/config.py [in /home/huydq17/PycharmProjects/agentstats-api/app/app.py:105]
2016-10-04 17:28:23,714 INFO: App log folder: /home/huydq17/PycharmProjects/agentstats-api/logs [in /home/huydq17/PycharmProjects/agentstats-api/app/app.py:106]
2016-10-04 17:29:29,917 INFO: Config filename: app/config.py [in /home/huydq17/PycharmProjects/agentstats-api/app/app.py:105]
2016-10-04 17:29:29,917 INFO: App log folder: /home/huydq17/PycharmProjects/agentstats-api/logs [in /home/huydq17/PycharmProjects/agentstats-api/app/app.py:106]
2016-10-04 17:30:40,792 INFO: Config filename: app/config.py [in /home/huydq17/PycharmProjects/agentstats-api/app/app.py:105]
2016-10-04 17:30:40,793 INFO: App log folder: /home/huydq17/PycharmProjects/agentstats-api/logs [in /home/huydq17/PycharmProjects/agentstats-api/app/app.py:106]
2016-10-04 17:31:50,536 INFO: Config filename: app/config.py [in /home/huydq17/PycharmProjects/agentstats-api/app/app.py:105]
2016-10-04 17:31:50,536 INFO: App log folder: /home/huydq17/PycharmProjects/agentstats-api/logs [in /home/huydq17/PycharmProjects/agentstats-api/app/app.py:106]
2016-10-06 15:50:36,025 INFO: Config filename: app/config.py [in /home/huydq17/PycharmProjects/agentstats-api/app/app.py:105]
2016-10-06 15:50:36,111 INFO: App log folder: /home/huydq17/PycharmProjects/agentstats-api/logs [in /home/huydq17/PycharmProjects/agentstats-api/app/app.py:106]
2016-10-06 16:57:59,631 INFO: Config filename: app/config.py [in /home/huydq17/PycharmProjects/agentstats-api/app/app.py:105]
2016-10-06 16:57:59,632 INFO: App log folder: /home/huydq17/PycharmProjects/agentstats-api/logs [in /home/huydq17/PycharmProjects/agentstats-api/app/app.py:106]
2016-10-06 16:58:46,246 INFO: Config filename: app/config.py [in /home/huydq17/PycharmProjects/agentstats-api/app/app.py:105]
2016-10-06 16:58:46,247 INFO: App log folder: /home/huydq17/PycharmProjects/agentstats-api/logs [in /home/huydq17/PycharmProjects/agentstats-api/app/app.py:106]
2016-10-06 16:59:54,344 ERROR: HTTP_STATUS_CODE_422: {'message': 'Validation error, re-check your data.', 'code': 422} [in /home/huydq17/PycharmProjects/agentstats-api/app/exceptions.py:191]
Traceback (most recent call last):
  File "/usr/local/lib/python2.7/dist-packages/flask/app.py", line 1475, in full_dispatch_request
    rv = self.dispatch_request()
  File "/usr/local/lib/python2.7/dist-packages/flask/app.py", line 1461, in dispatch_request
    return self.view_functions[rule.endpoint](**req.view_args)
  File "/usr/local/lib/python2.7/dist-packages/flask_oauth2/resources/__init__.py", line 50, in decorated
    return f(*args, **kwargs)
  File "/home/huydq17/PycharmProjects/agentstats-api/app/api/agent.py", line 73, in add_agent
    json_data = parser.parse(params)
  File "/usr/local/lib/python2.7/dist-packages/webargs/core.py", line 330, in parse
    self._on_validation_error(error)
  File "/usr/local/lib/python2.7/dist-packages/webargs/core.py", line 279, in _on_validation_error
    self.handle_error(error)
  File "/usr/local/lib/python2.7/dist-packages/webargs/flaskparser.py", line 99, in handle_error
    abort(status_code, messages=error.messages, exc=error)
  File "/usr/local/lib/python2.7/dist-packages/webargs/flaskparser.py", line 39, in abort
    raise err
UnprocessableEntity: 422: Unprocessable Entity
2016-10-06 17:00:31,911 ERROR: HTTP_STATUS_CODE_422: {'message': 'Validation error, re-check your data.', 'code': 422} [in /home/huydq17/PycharmProjects/agentstats-api/app/exceptions.py:191]
Traceback (most recent call last):
  File "/usr/local/lib/python2.7/dist-packages/flask/app.py", line 1475, in full_dispatch_request
    rv = self.dispatch_request()
  File "/usr/local/lib/python2.7/dist-packages/flask/app.py", line 1461, in dispatch_request
    return self.view_functions[rule.endpoint](**req.view_args)
  File "/usr/local/lib/python2.7/dist-packages/flask_oauth2/resources/__init__.py", line 50, in decorated
    return f(*args, **kwargs)
  File "/home/huydq17/PycharmProjects/agentstats-api/app/api/agent.py", line 73, in add_agent
    json_data = parser.parse(params)
  File "/usr/local/lib/python2.7/dist-packages/webargs/core.py", line 330, in parse
    self._on_validation_error(error)
  File "/usr/local/lib/python2.7/dist-packages/webargs/core.py", line 279, in _on_validation_error
    self.handle_error(error)
  File "/usr/local/lib/python2.7/dist-packages/webargs/flaskparser.py", line 99, in handle_error
    abort(status_code, messages=error.messages, exc=error)
  File "/usr/local/lib/python2.7/dist-packages/webargs/flaskparser.py", line 39, in abort
    raise err
UnprocessableEntity: 422: Unprocessable Entity
2016-10-06 17:01:38,019 ERROR: HTTP_STATUS_CODE_422: {'message': 'Validation error, re-check your data.', 'code': 422} [in /home/huydq17/PycharmProjects/agentstats-api/app/exceptions.py:191]
Traceback (most recent call last):
  File "/usr/local/lib/python2.7/dist-packages/flask/app.py", line 1475, in full_dispatch_request
    rv = self.dispatch_request()
  File "/usr/local/lib/python2.7/dist-packages/flask/app.py", line 1461, in dispatch_request
    return self.view_functions[rule.endpoint](**req.view_args)
  File "/usr/local/lib/python2.7/dist-packages/flask_oauth2/resources/__init__.py", line 50, in decorated
    return f(*args, **kwargs)
  File "/home/huydq17/PycharmProjects/agentstats-api/app/api/agent.py", line 73, in add_agent
    json_data = parser.parse(params)
  File "/usr/local/lib/python2.7/dist-packages/webargs/core.py", line 330, in parse
    self._on_validation_error(error)
  File "/usr/local/lib/python2.7/dist-packages/webargs/core.py", line 279, in _on_validation_error
    self.handle_error(error)
  File "/usr/local/lib/python2.7/dist-packages/webargs/flaskparser.py", line 99, in handle_error
    abort(status_code, messages=error.messages, exc=error)
  File "/usr/local/lib/python2.7/dist-packages/webargs/flaskparser.py", line 39, in abort
    raise err
UnprocessableEntity: 422: Unprocessable Entity
2016-10-06 17:01:57,411 INFO: Config filename: app/config.py [in /home/huydq17/PycharmProjects/agentstats-api/app/app.py:105]
2016-10-06 17:01:57,412 INFO: App log folder: /home/huydq17/PycharmProjects/agentstats-api/logs [in /home/huydq17/PycharmProjects/agentstats-api/app/app.py:106]
2016-10-06 17:04:09,836 INFO: Config filename: app/config.py [in /home/huydq17/PycharmProjects/agentstats-api/app/app.py:105]
2016-10-06 17:04:09,837 INFO: App log folder: /home/huydq17/PycharmProjects/agentstats-api/logs [in /home/huydq17/PycharmProjects/agentstats-api/app/app.py:106]
2016-10-06 17:05:30,489 INFO: Config filename: app/config.py [in /home/huydq17/PycharmProjects/agentstats-api/app/app.py:105]
2016-10-06 17:05:30,493 INFO: App log folder: /home/huydq17/PycharmProjects/agentstats-api/logs [in /home/huydq17/PycharmProjects/agentstats-api/app/app.py:106]
2016-10-06 17:06:13,855 INFO: Config filename: app/config.py [in /home/huydq17/PycharmProjects/agentstats-api/app/app.py:105]
2016-10-06 17:06:13,855 INFO: App log folder: /home/huydq17/PycharmProjects/agentstats-api/logs [in /home/huydq17/PycharmProjects/agentstats-api/app/app.py:106]
2016-10-06 17:06:53,042 INFO: Config filename: app/config.py [in /home/huydq17/PycharmProjects/agentstats-api/app/app.py:105]
2016-10-06 17:06:53,043 INFO: App log folder: /home/huydq17/PycharmProjects/agentstats-api/logs [in /home/huydq17/PycharmProjects/agentstats-api/app/app.py:106]
2016-10-06 17:07:07,715 ERROR: HTTP_STATUS_CODE_400: {'message': 'Duplicate 10.10.0.1 & VTT', 'code': 1005} [in /home/huydq17/PycharmProjects/agentstats-api/app/exceptions.py:191]
Traceback (most recent call last):
  File "/usr/local/lib/python2.7/dist-packages/flask/app.py", line 1475, in full_dispatch_request
    rv = self.dispatch_request()
  File "/usr/local/lib/python2.7/dist-packages/flask/app.py", line 1461, in dispatch_request
    return self.view_functions[rule.endpoint](**req.view_args)
  File "/usr/local/lib/python2.7/dist-packages/flask_oauth2/resources/__init__.py", line 50, in decorated
    return f(*args, **kwargs)
  File "/home/huydq17/PycharmProjects/agentstats-api/app/api/agent.py", line 79, in add_agent
    raise exceptions.BadRequest(1005, ip, group)
BadRequest
2016-10-06 17:07:41,657 INFO: Config filename: app/config.py [in /home/huydq17/PycharmProjects/agentstats-api/app/app.py:105]
2016-10-06 17:07:41,658 INFO: App log folder: /home/huydq17/PycharmProjects/agentstats-api/logs [in /home/huydq17/PycharmProjects/agentstats-api/app/app.py:106]
2016-10-06 17:07:42,465 ERROR: HTTP_STATUS_CODE_400: {'message': 'Duplicate Agent IP & Group', 'code': 1005} [in /home/huydq17/PycharmProjects/agentstats-api/app/exceptions.py:191]
Traceback (most recent call last):
  File "/usr/local/lib/python2.7/dist-packages/flask/app.py", line 1475, in full_dispatch_request
    rv = self.dispatch_request()
  File "/usr/local/lib/python2.7/dist-packages/flask/app.py", line 1461, in dispatch_request
    return self.view_functions[rule.endpoint](**req.view_args)
  File "/usr/local/lib/python2.7/dist-packages/flask_oauth2/resources/__init__.py", line 50, in decorated
    return f(*args, **kwargs)
  File "/home/huydq17/PycharmProjects/agentstats-api/app/api/agent.py", line 79, in add_agent
    raise exceptions.BadRequest(1005, 'Agent IP & Group')
BadRequest
2016-10-07 10:59:01,467 INFO: Config filename: app/config.py [in /home/huydq17/PycharmProjects/agentstats-api/app/app.py:105]
2016-10-07 10:59:01,484 INFO: App log folder: /home/huydq17/PycharmProjects/agentstats-api/logs [in /home/huydq17/PycharmProjects/agentstats-api/app/app.py:106]
2016-10-10 09:56:19,787 INFO: Config filename: app/config.py [in /home/huydq17/PycharmProjects/agentstats-api/app/app.py:105]
2016-10-10 09:56:19,829 INFO: App log folder: /home/huydq17/PycharmProjects/agentstats-api/logs [in /home/huydq17/PycharmProjects/agentstats-api/app/app.py:106]
2016-10-10 10:56:25,194 INFO: Config filename: app/config.py [in /home/huydq17/PycharmProjects/agentstats-api/app/app.py:105]
2016-10-10 10:56:25,198 INFO: App log folder: /home/huydq17/PycharmProjects/agentstats-api/logs [in /home/huydq17/PycharmProjects/agentstats-api/app/app.py:106]
2016-10-10 10:58:19,811 ERROR: HTTP_STATUS_CODE_400: {'message': 'Duplicate Agent IP & Group', 'code': 1005} [in /home/huydq17/PycharmProjects/agentstats-api/app/exceptions.py:191]
Traceback (most recent call last):
  File "/usr/local/lib/python2.7/dist-packages/flask/app.py", line 1475, in full_dispatch_request
    rv = self.dispatch_request()
  File "/usr/local/lib/python2.7/dist-packages/flask/app.py", line 1461, in dispatch_request
    return self.view_functions[rule.endpoint](**req.view_args)
  File "/usr/local/lib/python2.7/dist-packages/flask_oauth2/resources/__init__.py", line 50, in decorated
    return f(*args, **kwargs)
  File "/home/huydq17/PycharmProjects/agentstats-api/app/api/agent.py", line 107, in add_agent
    raise exceptions.BadRequest(1005, 'Agent IP & Group')
BadRequest
2016-10-10 11:15:07,316 INFO: Config filename: app/config.py [in /home/huydq17/PycharmProjects/agentstats-api/app/app.py:105]
2016-10-10 11:15:07,318 INFO: App log folder: /home/huydq17/PycharmProjects/agentstats-api/logs [in /home/huydq17/PycharmProjects/agentstats-api/app/app.py:106]
2016-10-10 11:26:50,077 INFO: Config filename: app/config.py [in /home/huydq17/PycharmProjects/agentstats-api/app/app.py:105]
2016-10-10 11:26:50,077 INFO: App log folder: /home/huydq17/PycharmProjects/agentstats-api/logs [in /home/huydq17/PycharmProjects/agentstats-api/app/app.py:106]
2016-10-10 11:30:29,879 ERROR: HTTP_STATUS_CODE_500: {'message': 'Internal Server Error.', 'code': 500} [in /home/huydq17/PycharmProjects/agentstats-api/app/exceptions.py:191]
Traceback (most recent call last):
  File "/usr/local/lib/python2.7/dist-packages/flask/app.py", line 1475, in full_dispatch_request
    rv = self.dispatch_request()
  File "/usr/local/lib/python2.7/dist-packages/flask/app.py", line 1461, in dispatch_request
    return self.view_functions[rule.endpoint](**req.view_args)
  File "/usr/local/lib/python2.7/dist-packages/flask_oauth2/resources/__init__.py", line 50, in decorated
    return f(*args, **kwargs)
  File "/home/huydq17/PycharmProjects/agentstats-api/app/api/agent.py", line 160, in edit_agent
    'ossec': json_data.get('ossec', data[0].get('ossec', 0)),
KeyError: 0
2016-10-10 11:30:59,153 ERROR: HTTP_STATUS_CODE_500: {'message': 'Internal Server Error.', 'code': 500} [in /home/huydq17/PycharmProjects/agentstats-api/app/exceptions.py:191]
Traceback (most recent call last):
  File "/usr/local/lib/python2.7/dist-packages/flask/app.py", line 1475, in full_dispatch_request
    rv = self.dispatch_request()
  File "/usr/local/lib/python2.7/dist-packages/flask/app.py", line 1461, in dispatch_request
    return self.view_functions[rule.endpoint](**req.view_args)
  File "/usr/local/lib/python2.7/dist-packages/flask_oauth2/resources/__init__.py", line 50, in decorated
    return f(*args, **kwargs)
  File "/home/huydq17/PycharmProjects/agentstats-api/app/api/agent.py", line 160, in edit_agent
    'ossec': json_data.get('ossec', data[0].get('ossec', 0)),
KeyError: 0
2016-10-10 11:31:19,212 INFO: Config filename: app/config.py [in /home/huydq17/PycharmProjects/agentstats-api/app/app.py:105]
2016-10-10 11:31:19,213 INFO: App log folder: /home/huydq17/PycharmProjects/agentstats-api/logs [in /home/huydq17/PycharmProjects/agentstats-api/app/app.py:106]
2016-10-10 11:38:46,153 ERROR: HTTP_STATUS_CODE_422: {'message': 'Validation error, re-check your data.', 'code': 422} [in /home/huydq17/PycharmProjects/agentstats-api/app/exceptions.py:191]
Traceback (most recent call last):
  File "/usr/local/lib/python2.7/dist-packages/flask/app.py", line 1475, in full_dispatch_request
    rv = self.dispatch_request()
  File "/usr/local/lib/python2.7/dist-packages/flask/app.py", line 1461, in dispatch_request
    return self.view_functions[rule.endpoint](**req.view_args)
  File "/usr/local/lib/python2.7/dist-packages/flask_oauth2/resources/__init__.py", line 50, in decorated
    return f(*args, **kwargs)
  File "/home/huydq17/PycharmProjects/agentstats-api/app/api/agent.py", line 148, in edit_agent
    json_data = parser.parse(params)
  File "/usr/local/lib/python2.7/dist-packages/webargs/core.py", line 330, in parse
    self._on_validation_error(error)
  File "/usr/local/lib/python2.7/dist-packages/webargs/core.py", line 279, in _on_validation_error
    self.handle_error(error)
  File "/usr/local/lib/python2.7/dist-packages/webargs/flaskparser.py", line 99, in handle_error
    abort(status_code, messages=error.messages, exc=error)
  File "/usr/local/lib/python2.7/dist-packages/webargs/flaskparser.py", line 39, in abort
    raise err
UnprocessableEntity: 422: Unprocessable Entity
2016-10-10 11:40:43,326 INFO: Config filename: app/config.py [in /home/huydq17/PycharmProjects/agentstats-api/app/app.py:105]
2016-10-10 11:40:43,327 INFO: App log folder: /home/huydq17/PycharmProjects/agentstats-api/logs [in /home/huydq17/PycharmProjects/agentstats-api/app/app.py:106]
2016-10-10 11:43:34,439 ERROR: HTTP_STATUS_CODE_422: {'message': 'Validation error, re-check your data.', 'code': 422} [in /home/huydq17/PycharmProjects/agentstats-api/app/exceptions.py:191]
Traceback (most recent call last):
  File "/usr/local/lib/python2.7/dist-packages/flask/app.py", line 1475, in full_dispatch_request
    rv = self.dispatch_request()
  File "/usr/local/lib/python2.7/dist-packages/flask/app.py", line 1461, in dispatch_request
    return self.view_functions[rule.endpoint](**req.view_args)
  File "/usr/local/lib/python2.7/dist-packages/flask_oauth2/resources/__init__.py", line 50, in decorated
    return f(*args, **kwargs)
  File "/home/huydq17/PycharmProjects/agentstats-api/app/api/agent.py", line 148, in edit_agent
    json_data = parser.parse(params)
  File "/usr/local/lib/python2.7/dist-packages/webargs/core.py", line 330, in parse
    self._on_validation_error(error)
  File "/usr/local/lib/python2.7/dist-packages/webargs/core.py", line 279, in _on_validation_error
    self.handle_error(error)
  File "/usr/local/lib/python2.7/dist-packages/webargs/flaskparser.py", line 99, in handle_error
    abort(status_code, messages=error.messages, exc=error)
  File "/usr/local/lib/python2.7/dist-packages/webargs/flaskparser.py", line 39, in abort
    raise err
UnprocessableEntity: 422: Unprocessable Entity
2016-10-10 13:51:02,680 INFO: Config filename: app/config.py [in /home/huydq17/PycharmProjects/agentstats-api/app/app.py:105]
2016-10-10 13:51:02,681 INFO: App log folder: /home/huydq17/PycharmProjects/agentstats-api/logs [in /home/huydq17/PycharmProjects/agentstats-api/app/app.py:106]
2016-10-10 14:07:13,569 INFO: Config filename: app/config.py [in /home/huydq17/PycharmProjects/agentstats-api/app/app.py:105]
2016-10-10 14:07:13,569 INFO: App log folder: /home/huydq17/PycharmProjects/agentstats-api/logs [in /home/huydq17/PycharmProjects/agentstats-api/app/app.py:106]
2016-10-10 14:07:17,635 ERROR: HTTP_STATUS_CODE_401: {'message': 'You do not have permission to access', 'code': 2000} [in /home/huydq17/PycharmProjects/agentstats-api/app/exceptions.py:191]
Traceback (most recent call last):
  File "/usr/local/lib/python2.7/dist-packages/flask/app.py", line 1475, in full_dispatch_request
    rv = self.dispatch_request()
  File "/usr/local/lib/python2.7/dist-packages/flask/app.py", line 1461, in dispatch_request
    return self.view_functions[rule.endpoint](**req.view_args)
  File "/usr/local/lib/python2.7/dist-packages/flask_oauth2/resources/__init__.py", line 50, in decorated
    return f(*args, **kwargs)
  File "/usr/local/lib/python2.7/dist-packages/flask_permissions/permissions/__init__.py", line 56, in decorated
    return abort(401, {'code': 2000, 'message': 'You do not have permission to access'})
  File "/usr/local/lib/python2.7/dist-packages/werkzeug/exceptions.py", line 605, in __call__
    raise self.mapping[code](*args, **kwargs)
Unauthorized: 401: Unauthorized
2017-06-16 09:09:18,964 INFO: Config filename: app/config.py [in /home/huydq17/GitProjects/agentstats-api/app/app.py:107]
2017-06-16 09:09:18,990 INFO: App log folder: /home/huydq17/GitProjects/agentstats-api/logs [in /home/huydq17/GitProjects/agentstats-api/app/app.py:108]
2017-06-16 09:09:33,309 INFO: Config filename: app/config.py [in /home/huydq17/GitProjects/agentstats-api/app/app.py:107]
2017-06-16 09:09:33,310 INFO: App log folder: /home/huydq17/GitProjects/agentstats-api/logs [in /home/huydq17/GitProjects/agentstats-api/app/app.py:108]
2017-06-16 09:10:13,014 INFO: Config filename: app/config.py [in /home/huydq17/GitProjects/agentstats-api/app/app.py:107]
2017-06-16 09:10:13,015 INFO: App log folder: /home/huydq17/GitProjects/agentstats-api/logs [in /home/huydq17/GitProjects/agentstats-api/app/app.py:108]
2017-06-16 17:33:09,733 INFO: Config filename: app/config.py [in /home/huydq17/GitProjects/agentstats-api/app/app.py:107]
2017-06-16 17:33:09,739 INFO: App log folder: /home/huydq17/GitProjects/agentstats-api/logs [in /home/huydq17/GitProjects/agentstats-api/app/app.py:108]
2017-06-16 17:34:16,785 INFO: Config filename: app/config.py [in /home/huydq17/GitProjects/agentstats-api/app/app.py:107]
2017-06-16 17:34:16,785 INFO: App log folder: /home/huydq17/GitProjects/agentstats-api/logs [in /home/huydq17/GitProjects/agentstats-api/app/app.py:108]
2017-06-16 17:34:25,956 ERROR: HTTP_STATUS_CODE_422: {'message': 'Validation error, re-check your data.', 'code': 422} [in /home/huydq17/GitProjects/agentstats-api/app/exceptions.py:191]
Traceback (most recent call last):
  File "/usr/local/lib/python2.7/dist-packages/flask/app.py", line 1475, in full_dispatch_request
    rv = self.dispatch_request()
  File "/usr/local/lib/python2.7/dist-packages/flask/app.py", line 1461, in dispatch_request
    return self.view_functions[rule.endpoint](**req.view_args)
  File "/usr/local/lib/python2.7/dist-packages/flask_oauth2/resources/__init__.py", line 37, in decorated
    return f(*args, **kwargs)
  File "/usr/local/lib/python2.7/dist-packages/flask_permissions/permissions/__init__.py", line 57, in decorated
    return f(*args, **kwargs)
  File "/home/huydq17/GitProjects/agentstats-api/app/api/minion.py", line 40, in list_minions
    args = parser.parse(params)
  File "/usr/local/lib/python2.7/dist-packages/webargs/core.py", line 330, in parse
    self._on_validation_error(error)
  File "/usr/local/lib/python2.7/dist-packages/webargs/core.py", line 279, in _on_validation_error
    self.handle_error(error)
  File "/usr/local/lib/python2.7/dist-packages/webargs/flaskparser.py", line 99, in handle_error
    abort(status_code, messages=error.messages, exc=error)
  File "/usr/local/lib/python2.7/dist-packages/webargs/flaskparser.py", line 39, in abort
    raise err
UnprocessableEntity: 422: Unprocessable Entity
2017-06-16 17:36:20,414 ERROR: HTTP_STATUS_CODE_422: {'message': 'Validation error, re-check your data.', 'code': 422} [in /home/huydq17/GitProjects/agentstats-api/app/exceptions.py:191]
Traceback (most recent call last):
  File "/usr/local/lib/python2.7/dist-packages/flask/app.py", line 1475, in full_dispatch_request
    rv = self.dispatch_request()
  File "/usr/local/lib/python2.7/dist-packages/flask/app.py", line 1461, in dispatch_request
    return self.view_functions[rule.endpoint](**req.view_args)
  File "/usr/local/lib/python2.7/dist-packages/flask_oauth2/resources/__init__.py", line 37, in decorated
    return f(*args, **kwargs)
  File "/usr/local/lib/python2.7/dist-packages/flask_permissions/permissions/__init__.py", line 57, in decorated
    return f(*args, **kwargs)
  File "/home/huydq17/GitProjects/agentstats-api/app/api/minion.py", line 40, in list_minions
    args = parser.parse(params)
  File "/usr/local/lib/python2.7/dist-packages/webargs/core.py", line 330, in parse
    self._on_validation_error(error)
  File "/usr/local/lib/python2.7/dist-packages/webargs/core.py", line 279, in _on_validation_error
    self.handle_error(error)
  File "/usr/local/lib/python2.7/dist-packages/webargs/flaskparser.py", line 99, in handle_error
    abort(status_code, messages=error.messages, exc=error)
  File "/usr/local/lib/python2.7/dist-packages/webargs/flaskparser.py", line 39, in abort
    raise err
UnprocessableEntity: 422: Unprocessable Entity
2017-06-16 17:38:07,983 ERROR: HTTP_STATUS_CODE_422: {'message': 'Validation error, re-check your data.', 'code': 422} [in /home/huydq17/GitProjects/agentstats-api/app/exceptions.py:191]
Traceback (most recent call last):
  File "/usr/local/lib/python2.7/dist-packages/flask/app.py", line 1475, in full_dispatch_request
    rv = self.dispatch_request()
  File "/usr/local/lib/python2.7/dist-packages/flask/app.py", line 1461, in dispatch_request
    return self.view_functions[rule.endpoint](**req.view_args)
  File "/usr/local/lib/python2.7/dist-packages/flask_oauth2/resources/__init__.py", line 37, in decorated
    return f(*args, **kwargs)
  File "/usr/local/lib/python2.7/dist-packages/flask_permissions/permissions/__init__.py", line 57, in decorated
    return f(*args, **kwargs)
  File "/home/huydq17/GitProjects/agentstats-api/app/api/minion.py", line 40, in list_minions
    params['group'] = [group]
  File "/usr/local/lib/python2.7/dist-packages/webargs/core.py", line 330, in parse
    self._on_validation_error(error)
  File "/usr/local/lib/python2.7/dist-packages/webargs/core.py", line 279, in _on_validation_error
    self.handle_error(error)
  File "/usr/local/lib/python2.7/dist-packages/webargs/flaskparser.py", line 99, in handle_error
    abort(status_code, messages=error.messages, exc=error)
  File "/usr/local/lib/python2.7/dist-packages/webargs/flaskparser.py", line 39, in abort
    raise err
UnprocessableEntity: 422: Unprocessable Entity
2017-06-16 17:39:55,272 INFO: Config filename: app/config.py [in /home/huydq17/GitProjects/agentstats-api/app/app.py:107]
2017-06-16 17:39:55,273 INFO: App log folder: /home/huydq17/GitProjects/agentstats-api/logs [in /home/huydq17/GitProjects/agentstats-api/app/app.py:108]
2017-06-16 17:41:59,776 INFO: Config filename: app/config.py [in /home/huydq17/GitProjects/agentstats-api/app/app.py:107]
2017-06-16 17:41:59,776 INFO: App log folder: /home/huydq17/GitProjects/agentstats-api/logs [in /home/huydq17/GitProjects/agentstats-api/app/app.py:108]
2017-06-16 17:45:37,895 INFO: Config filename: app/config.py [in /home/huydq17/GitProjects/agentstats-api/app/app.py:107]
2017-06-16 17:45:37,896 INFO: App log folder: /home/huydq17/GitProjects/agentstats-api/logs [in /home/huydq17/GitProjects/agentstats-api/app/app.py:108]
2017-11-09 04:29:02,856 INFO: Config filename: app/config.py [in /home/quynt13/Desktop/FW Xin FlaskAngular code template/Agentstats-Editted/agentstats-api/app/app.py:107]
2017-11-09 04:29:02,861 INFO: App log folder: /home/quynt13/Desktop/FW Xin FlaskAngular code template/Agentstats-Editted/agentstats-api/logs [in /home/quynt13/Desktop/FW Xin FlaskAngular code template/Agentstats-Editted/agentstats-api/app/app.py:108]
2017-11-09 04:47:11,997 INFO: Config filename: app/config.py [in /home/quynt13/Desktop/FW Xin FlaskAngular code template/Agentstats-Editted/agentstats-api/app/app.py:107]
2017-11-09 04:47:12,006 INFO: App log folder: /home/quynt13/Desktop/FW Xin FlaskAngular code template/Agentstats-Editted/agentstats-api/logs [in /home/quynt13/Desktop/FW Xin FlaskAngular code template/Agentstats-Editted/agentstats-api/app/app.py:108]
2017-11-09 04:52:49,168 INFO: Config filename: app/config.py [in /home/quynt13/Desktop/FW Xin FlaskAngular code template/Agentstats-Editted/agentstats-api/app/app.py:107]
2017-11-09 04:52:49,168 INFO: App log folder: /home/quynt13/Desktop/FW Xin FlaskAngular code template/Agentstats-Editted/agentstats-api/logs [in /home/quynt13/Desktop/FW Xin FlaskAngular code template/Agentstats-Editted/agentstats-api/app/app.py:108]
2017-11-09 05:10:27,568 INFO: Config filename: app/config.py [in /home/quynt13/Desktop/FW Xin FlaskAngular code template/Agentstats-Editted/agentstats-api/app/app.py:107]
2017-11-09 05:10:27,576 INFO: App log folder: /home/quynt13/Desktop/FW Xin FlaskAngular code template/Agentstats-Editted/agentstats-api/logs [in /home/quynt13/Desktop/FW Xin FlaskAngular code template/Agentstats-Editted/agentstats-api/app/app.py:108]
2017-11-09 06:02:12,274 INFO: Config filename: app/config.py [in /home/quynt13/Desktop/FW Xin FlaskAngular code template/Agentstats-Editted/agentstats-api/app/app.py:107]
2017-11-09 06:02:12,275 INFO: App log folder: /home/quynt13/Desktop/FW Xin FlaskAngular code template/Agentstats-Editted/agentstats-api/logs [in /home/quynt13/Desktop/FW Xin FlaskAngular code template/Agentstats-Editted/agentstats-api/app/app.py:108]
2017-11-09 07:36:04,853 INFO: Config filename: app/config.py [in /home/quynt13/Desktop/FW Xin FlaskAngular code template/Agentstats-Editted/agentstats-api/app/app.py:107]
2017-11-09 07:36:04,853 INFO: App log folder: /home/quynt13/Desktop/FW Xin FlaskAngular code template/Agentstats-Editted/agentstats-api/logs [in /home/quynt13/Desktop/FW Xin FlaskAngular code template/Agentstats-Editted/agentstats-api/app/app.py:108]
2017-11-09 08:10:42,202 INFO: Config filename: app/config.py [in /home/quynt13/Desktop/FW Xin FlaskAngular code template/Agentstats-Editted/agentstats-api/app/app.py:107]
2017-11-09 08:10:42,202 INFO: App log folder: /home/quynt13/Desktop/FW Xin FlaskAngular code template/Agentstats-Editted/agentstats-api/logs [in /home/quynt13/Desktop/FW Xin FlaskAngular code template/Agentstats-Editted/agentstats-api/app/app.py:108]
2017-11-09 08:13:35,984 INFO: Config filename: app/config.py [in /home/quynt13/Desktop/FW Xin FlaskAngular code template/Agentstats-Editted/agentstats-api/app/app.py:107]
2017-11-09 08:13:35,994 INFO: App log folder: /home/quynt13/Desktop/FW Xin FlaskAngular code template/Agentstats-Editted/agentstats-api/logs [in /home/quynt13/Desktop/FW Xin FlaskAngular code template/Agentstats-Editted/agentstats-api/app/app.py:108]
2017-11-09 22:42:59,413 INFO: Config filename: app/config.py [in /home/quynt13/Desktop/FW Xin FlaskAngular code template/Agentstats-Editted/agentstats-api/app/app.py:107]
2017-11-09 22:42:59,424 INFO: App log folder: /home/quynt13/Desktop/FW Xin FlaskAngular code template/Agentstats-Editted/agentstats-api/logs [in /home/quynt13/Desktop/FW Xin FlaskAngular code template/Agentstats-Editted/agentstats-api/app/app.py:108]
2017-11-09 22:46:45,677 INFO: Config filename: app/config.py [in /home/quynt13/Desktop/FW Xin FlaskAngular code template/Agentstats-Editted/agentstats-api/app/app.py:107]
2017-11-09 22:46:45,678 INFO: App log folder: /home/quynt13/Desktop/FW Xin FlaskAngular code template/Agentstats-Editted/agentstats-api/logs [in /home/quynt13/Desktop/FW Xin FlaskAngular code template/Agentstats-Editted/agentstats-api/app/app.py:108]
2017-11-09 22:50:08,687 INFO: Config filename: app/config.py [in /home/quynt13/Desktop/FW Xin FlaskAngular code template/Agentstats-Editted/agentstats-api/app/app.py:107]
2017-11-09 22:50:08,697 INFO: App log folder: /home/quynt13/Desktop/FW Xin FlaskAngular code template/Agentstats-Editted/agentstats-api/logs [in /home/quynt13/Desktop/FW Xin FlaskAngular code template/Agentstats-Editted/agentstats-api/app/app.py:108]
2017-11-09 23:03:31,064 INFO: Config filename: app/config.py [in /home/quynt13/Desktop/FW Xin FlaskAngular code template/Agentstats-Editted/agentstats-api/app/app.py:107]
2017-11-09 23:03:31,065 INFO: App log folder: /home/quynt13/Desktop/FW Xin FlaskAngular code template/Agentstats-Editted/agentstats-api/logs [in /home/quynt13/Desktop/FW Xin FlaskAngular code template/Agentstats-Editted/agentstats-api/app/app.py:108]
2017-11-09 23:03:40,383 INFO: Config filename: app/config.py [in /home/quynt13/Desktop/FW Xin FlaskAngular code template/Agentstats-Editted/agentstats-api/app/app.py:107]
2017-11-09 23:03:40,383 INFO: App log folder: /home/quynt13/Desktop/FW Xin FlaskAngular code template/Agentstats-Editted/agentstats-api/logs [in /home/quynt13/Desktop/FW Xin FlaskAngular code template/Agentstats-Editted/agentstats-api/app/app.py:108]
2017-11-09 23:32:12,668 INFO: Config filename: app/config.py [in /home/quynt13/Desktop/ACBank/agentstats-api/app/app.py:107]
2017-11-09 23:32:12,669 INFO: App log folder: /home/quynt13/Desktop/ACBank/agentstats-api/logs [in /home/quynt13/Desktop/ACBank/agentstats-api/app/app.py:108]
2017-11-10 00:52:49,957 INFO: Config filename: app/config.py [in /home/quynt13/Desktop/ACBank/agentstats-api/app/app.py:107]
2017-11-10 00:52:49,958 INFO: App log folder: /home/quynt13/Desktop/ACBank/agentstats-api/logs [in /home/quynt13/Desktop/ACBank/agentstats-api/app/app.py:108]
2017-11-10 04:17:57,047 INFO: Config filename: app/config.py [in /home/quynt13/Desktop/ACBank/agentstats-api/app/app.py:107]
2017-11-10 04:17:57,047 INFO: App log folder: /home/quynt13/Desktop/ACBank/agentstats-api/logs [in /home/quynt13/Desktop/ACBank/agentstats-api/app/app.py:108]
2017-11-10 05:18:50,671 INFO: Config filename: app/config.py [in /home/quynt13/Desktop/ACBank/agentstats-api/app/app.py:107]
2017-11-10 05:18:50,672 INFO: App log folder: /home/quynt13/Desktop/ACBank/agentstats-api/logs [in /home/quynt13/Desktop/ACBank/agentstats-api/app/app.py:108]
2017-11-10 06:58:54,916 INFO: Config filename: app/config.py [in /home/quynt13/Desktop/ACBank/agentstats-api/app/app.py:107]
2017-11-10 06:58:54,917 INFO: App log folder: /home/quynt13/Desktop/ACBank/agentstats-api/logs [in /home/quynt13/Desktop/ACBank/agentstats-api/app/app.py:108]
2017-11-10 07:21:51,640 INFO: Config filename: app/config.py [in /home/quynt13/Desktop/ACBank/agentstats-api/app/app.py:107]
2017-11-10 07:21:51,641 INFO: App log folder: /home/quynt13/Desktop/ACBank/agentstats-api/logs [in /home/quynt13/Desktop/ACBank/agentstats-api/app/app.py:108]
2017-11-10 07:28:17,935 INFO: Config filename: app/config.py [in /home/quynt13/Desktop/ACBank/agentstats-api/app/app.py:107]
2017-11-10 07:28:17,935 INFO: App log folder: /home/quynt13/Desktop/ACBank/agentstats-api/logs [in /home/quynt13/Desktop/ACBank/agentstats-api/app/app.py:108]
2017-11-10 07:30:39,576 INFO: Config filename: app/config.py [in /home/quynt13/Desktop/ACBank/agentstats-api/app/app.py:107]
2017-11-10 07:30:39,576 INFO: App log folder: /home/quynt13/Desktop/ACBank/agentstats-api/logs [in /home/quynt13/Desktop/ACBank/agentstats-api/app/app.py:108]
2017-11-10 07:31:20,977 INFO: Config filename: app/config.py [in /home/quynt13/Desktop/ACBank/agentstats-api/app/app.py:107]
2017-11-10 07:31:20,977 INFO: App log folder: /home/quynt13/Desktop/ACBank/agentstats-api/logs [in /home/quynt13/Desktop/ACBank/agentstats-api/app/app.py:108]
2017-11-10 07:32:28,584 INFO: Config filename: app/config.py [in /home/quynt13/Desktop/ACBank/agentstats-api/app/app.py:107]
2017-11-10 07:32:28,585 INFO: App log folder: /home/quynt13/Desktop/ACBank/agentstats-api/logs [in /home/quynt13/Desktop/ACBank/agentstats-api/app/app.py:108]
2017-11-10 07:33:27,165 INFO: Config filename: app/config.py [in /home/quynt13/Desktop/ACBank/agentstats-api/app/app.py:107]
2017-11-10 07:33:27,165 INFO: App log folder: /home/quynt13/Desktop/ACBank/agentstats-api/logs [in /home/quynt13/Desktop/ACBank/agentstats-api/app/app.py:108]
2017-11-10 07:33:49,215 ERROR: HTTP_STATUS_CODE_500: {'message': 'Internal Server Error.', 'code': 500} [in /home/quynt13/Desktop/ACBank/agentstats-api/app/exceptions.py:191]
Traceback (most recent call last):
  File "/usr/local/lib/python2.7/dist-packages/flask/app.py", line 1612, in full_dispatch_request
    rv = self.dispatch_request()
  File "/usr/local/lib/python2.7/dist-packages/flask/app.py", line 1598, in dispatch_request
    return self.view_functions[rule.endpoint](**req.view_args)
  File "/usr/local/lib/python2.7/dist-packages/flask_oauth2/resources/__init__.py", line 37, in decorated
    return f(*args, **kwargs)
  File "/usr/local/lib/python2.7/dist-packages/flask_permissions/permissions/__init__.py", line 57, in decorated
    return f(*args, **kwargs)
  File "/home/quynt13/Desktop/ACBank/agentstats-api/app/api/minion.py", line 81, in list_minions
    return jsonify(result)
  File "/usr/local/lib/python2.7/dist-packages/flask/json.py", line 263, in jsonify
    (dumps(data, indent=indent, separators=separators), '\n'),
  File "/usr/local/lib/python2.7/dist-packages/flask/json.py", line 123, in dumps
    rv = _json.dumps(obj, **kwargs)
  File "/usr/lib/python2.7/json/__init__.py", line 250, in dumps
    sort_keys=sort_keys, **kw).encode(obj)
  File "/usr/lib/python2.7/json/encoder.py", line 209, in encode
    chunks = list(chunks)
  File "/usr/lib/python2.7/json/encoder.py", line 434, in _iterencode
    for chunk in _iterencode_dict(o, _current_indent_level):
  File "/usr/lib/python2.7/json/encoder.py", line 408, in _iterencode_dict
    for chunk in chunks:
  File "/usr/lib/python2.7/json/encoder.py", line 332, in _iterencode_list
    for chunk in chunks:
  File "/usr/lib/python2.7/json/encoder.py", line 408, in _iterencode_dict
    for chunk in chunks:
  File "/usr/lib/python2.7/json/encoder.py", line 442, in _iterencode
    o = _default(o)
  File "/usr/local/lib/python2.7/dist-packages/flask/json.py", line 80, in default
    return _json.JSONEncoder.default(self, o)
  File "/usr/lib/python2.7/json/encoder.py", line 184, in default
    raise TypeError(repr(o) + " is not JSON serializable")
TypeError: ObjectId('5916c0b5fdbcfc37a0155020') is not JSON serializable
2017-11-10 07:33:49,587 ERROR: HTTP_STATUS_CODE_500: {'message': 'Internal Server Error.', 'code': 500} [in /home/quynt13/Desktop/ACBank/agentstats-api/app/exceptions.py:191]
Traceback (most recent call last):
  File "/usr/local/lib/python2.7/dist-packages/flask/app.py", line 1612, in full_dispatch_request
    rv = self.dispatch_request()
  File "/usr/local/lib/python2.7/dist-packages/flask/app.py", line 1598, in dispatch_request
    return self.view_functions[rule.endpoint](**req.view_args)
  File "/usr/local/lib/python2.7/dist-packages/flask_oauth2/resources/__init__.py", line 37, in decorated
    return f(*args, **kwargs)
  File "/usr/local/lib/python2.7/dist-packages/flask_permissions/permissions/__init__.py", line 57, in decorated
    return f(*args, **kwargs)
  File "/home/quynt13/Desktop/ACBank/agentstats-api/app/api/minion.py", line 81, in list_minions
    return jsonify(result)
  File "/usr/local/lib/python2.7/dist-packages/flask/json.py", line 263, in jsonify
    (dumps(data, indent=indent, separators=separators), '\n'),
  File "/usr/local/lib/python2.7/dist-packages/flask/json.py", line 123, in dumps
    rv = _json.dumps(obj, **kwargs)
  File "/usr/lib/python2.7/json/__init__.py", line 250, in dumps
    sort_keys=sort_keys, **kw).encode(obj)
  File "/usr/lib/python2.7/json/encoder.py", line 209, in encode
    chunks = list(chunks)
  File "/usr/lib/python2.7/json/encoder.py", line 434, in _iterencode
    for chunk in _iterencode_dict(o, _current_indent_level):
  File "/usr/lib/python2.7/json/encoder.py", line 408, in _iterencode_dict
    for chunk in chunks:
  File "/usr/lib/python2.7/json/encoder.py", line 332, in _iterencode_list
    for chunk in chunks:
  File "/usr/lib/python2.7/json/encoder.py", line 408, in _iterencode_dict
    for chunk in chunks:
  File "/usr/lib/python2.7/json/encoder.py", line 442, in _iterencode
    o = _default(o)
  File "/usr/local/lib/python2.7/dist-packages/flask/json.py", line 80, in default
    return _json.JSONEncoder.default(self, o)
  File "/usr/lib/python2.7/json/encoder.py", line 184, in default
    raise TypeError(repr(o) + " is not JSON serializable")
TypeError: ObjectId('5916c0b5fdbcfc37a0155020') is not JSON serializable
2017-11-10 07:36:59,256 INFO: Config filename: app/config.py [in /home/quynt13/Desktop/ACBank/agentstats-api/app/app.py:107]
2017-11-10 07:36:59,256 INFO: App log folder: /home/quynt13/Desktop/ACBank/agentstats-api/logs [in /home/quynt13/Desktop/ACBank/agentstats-api/app/app.py:108]
2017-11-10 07:45:09,482 INFO: Config filename: app/config.py [in /home/quynt13/Desktop/ACBank/agentstats-api/app/app.py:107]
2017-11-10 07:45:09,482 INFO: App log folder: /home/quynt13/Desktop/ACBank/agentstats-api/logs [in /home/quynt13/Desktop/ACBank/agentstats-api/app/app.py:108]
2017-11-10 07:50:35,218 ERROR: HTTP_STATUS_CODE_500: {'message': 'Internal Server Error.', 'code': 500} [in /home/quynt13/Desktop/ACBank/agentstats-api/app/exceptions.py:191]
Traceback (most recent call last):
  File "/usr/local/lib/python2.7/dist-packages/flask/app.py", line 1612, in full_dispatch_request
    rv = self.dispatch_request()
  File "/usr/local/lib/python2.7/dist-packages/flask/app.py", line 1598, in dispatch_request
    return self.view_functions[rule.endpoint](**req.view_args)
  File "/usr/local/lib/python2.7/dist-packages/flask_oauth2/resources/__init__.py", line 37, in decorated
    return f(*args, **kwargs)
  File "/usr/local/lib/python2.7/dist-packages/flask_permissions/permissions/__init__.py", line 57, in decorated
    return f(*args, **kwargs)
  File "/home/quynt13/Desktop/ACBank/agentstats-api/app/api/minion.py", line 81, in list_minions
    return jsonify(result)
  File "/usr/local/lib/python2.7/dist-packages/flask/json.py", line 263, in jsonify
    (dumps(data, indent=indent, separators=separators), '\n'),
  File "/usr/local/lib/python2.7/dist-packages/flask/json.py", line 123, in dumps
    rv = _json.dumps(obj, **kwargs)
  File "/usr/lib/python2.7/json/__init__.py", line 250, in dumps
    sort_keys=sort_keys, **kw).encode(obj)
  File "/usr/lib/python2.7/json/encoder.py", line 209, in encode
    chunks = list(chunks)
  File "/usr/lib/python2.7/json/encoder.py", line 434, in _iterencode
    for chunk in _iterencode_dict(o, _current_indent_level):
  File "/usr/lib/python2.7/json/encoder.py", line 408, in _iterencode_dict
    for chunk in chunks:
  File "/usr/lib/python2.7/json/encoder.py", line 332, in _iterencode_list
    for chunk in chunks:
  File "/usr/lib/python2.7/json/encoder.py", line 408, in _iterencode_dict
    for chunk in chunks:
  File "/usr/lib/python2.7/json/encoder.py", line 442, in _iterencode
    o = _default(o)
  File "/usr/local/lib/python2.7/dist-packages/flask/json.py", line 80, in default
    return _json.JSONEncoder.default(self, o)
  File "/usr/lib/python2.7/json/encoder.py", line 184, in default
    raise TypeError(repr(o) + " is not JSON serializable")
TypeError: ObjectId('5916c0b5fdbcfc37a0155020') is not JSON serializable
2017-11-10 07:53:18,599 INFO: Config filename: app/config.py [in /home/quynt13/Desktop/ACBank/agentstats-api/app/app.py:107]
2017-11-10 07:53:18,599 INFO: App log folder: /home/quynt13/Desktop/ACBank/agentstats-api/logs [in /home/quynt13/Desktop/ACBank/agentstats-api/app/app.py:108]
2017-11-10 07:54:50,672 ERROR: HTTP_STATUS_CODE_500: {'message': 'Internal Server Error.', 'code': 500} [in /home/quynt13/Desktop/ACBank/agentstats-api/app/exceptions.py:191]
Traceback (most recent call last):
  File "/usr/local/lib/python2.7/dist-packages/flask/app.py", line 1612, in full_dispatch_request
    rv = self.dispatch_request()
  File "/usr/local/lib/python2.7/dist-packages/flask/app.py", line 1598, in dispatch_request
    return self.view_functions[rule.endpoint](**req.view_args)
  File "/usr/local/lib/python2.7/dist-packages/flask_oauth2/resources/__init__.py", line 37, in decorated
    return f(*args, **kwargs)
  File "/usr/local/lib/python2.7/dist-packages/flask_permissions/permissions/__init__.py", line 57, in decorated
    return f(*args, **kwargs)
  File "/home/quynt13/Desktop/ACBank/agentstats-api/app/api/minion.py", line 81, in list_minions
    return jsonify(result)
  File "/usr/local/lib/python2.7/dist-packages/flask/json.py", line 263, in jsonify
    (dumps(data, indent=indent, separators=separators), '\n'),
  File "/usr/local/lib/python2.7/dist-packages/flask/json.py", line 123, in dumps
    rv = _json.dumps(obj, **kwargs)
  File "/usr/lib/python2.7/json/__init__.py", line 250, in dumps
    sort_keys=sort_keys, **kw).encode(obj)
  File "/usr/lib/python2.7/json/encoder.py", line 209, in encode
    chunks = list(chunks)
  File "/usr/lib/python2.7/json/encoder.py", line 434, in _iterencode
    for chunk in _iterencode_dict(o, _current_indent_level):
  File "/usr/lib/python2.7/json/encoder.py", line 408, in _iterencode_dict
    for chunk in chunks:
  File "/usr/lib/python2.7/json/encoder.py", line 332, in _iterencode_list
    for chunk in chunks:
  File "/usr/lib/python2.7/json/encoder.py", line 408, in _iterencode_dict
    for chunk in chunks:
  File "/usr/lib/python2.7/json/encoder.py", line 442, in _iterencode
    o = _default(o)
  File "/usr/local/lib/python2.7/dist-packages/flask/json.py", line 80, in default
    return _json.JSONEncoder.default(self, o)
  File "/usr/lib/python2.7/json/encoder.py", line 184, in default
    raise TypeError(repr(o) + " is not JSON serializable")
TypeError: ObjectId('5916c0b5fdbcfc37a0155020') is not JSON serializable
2017-11-10 07:55:48,241 INFO: Config filename: app/config.py [in /home/quynt13/Desktop/ACBank/agentstats-api/app/app.py:107]
2017-11-10 07:55:48,242 INFO: App log folder: /home/quynt13/Desktop/ACBank/agentstats-api/logs [in /home/quynt13/Desktop/ACBank/agentstats-api/app/app.py:108]
2017-11-10 07:58:18,805 INFO: Config filename: app/config.py [in /home/quynt13/Desktop/ACBank/agentstats-api/app/app.py:107]
2017-11-10 07:58:18,806 INFO: App log folder: /home/quynt13/Desktop/ACBank/agentstats-api/logs [in /home/quynt13/Desktop/ACBank/agentstats-api/app/app.py:108]
2017-11-10 07:59:52,500 ERROR: HTTP_STATUS_CODE_500: {'message': 'Internal Server Error.', 'code': 500} [in /home/quynt13/Desktop/ACBank/agentstats-api/app/exceptions.py:191]
Traceback (most recent call last):
  File "/usr/local/lib/python2.7/dist-packages/flask/app.py", line 1612, in full_dispatch_request
    rv = self.dispatch_request()
  File "/usr/local/lib/python2.7/dist-packages/flask/app.py", line 1598, in dispatch_request
    return self.view_functions[rule.endpoint](**req.view_args)
  File "/home/quynt13/Desktop/ACBank/agentstats-api/app/api/minion.py", line 81, in list_minions
    return jsonify(result)
  File "/usr/local/lib/python2.7/dist-packages/flask/json.py", line 263, in jsonify
    (dumps(data, indent=indent, separators=separators), '\n'),
  File "/usr/local/lib/python2.7/dist-packages/flask/json.py", line 123, in dumps
    rv = _json.dumps(obj, **kwargs)
  File "/usr/lib/python2.7/json/__init__.py", line 250, in dumps
    sort_keys=sort_keys, **kw).encode(obj)
  File "/usr/lib/python2.7/json/encoder.py", line 209, in encode
    chunks = list(chunks)
  File "/usr/lib/python2.7/json/encoder.py", line 434, in _iterencode
    for chunk in _iterencode_dict(o, _current_indent_level):
  File "/usr/lib/python2.7/json/encoder.py", line 408, in _iterencode_dict
    for chunk in chunks:
  File "/usr/lib/python2.7/json/encoder.py", line 332, in _iterencode_list
    for chunk in chunks:
  File "/usr/lib/python2.7/json/encoder.py", line 408, in _iterencode_dict
    for chunk in chunks:
  File "/usr/lib/python2.7/json/encoder.py", line 442, in _iterencode
    o = _default(o)
  File "/usr/local/lib/python2.7/dist-packages/flask/json.py", line 80, in default
    return _json.JSONEncoder.default(self, o)
  File "/usr/lib/python2.7/json/encoder.py", line 184, in default
    raise TypeError(repr(o) + " is not JSON serializable")
TypeError: ObjectId('5916c0b5fdbcfc37a0155020') is not JSON serializable
2017-11-10 08:00:08,644 ERROR: HTTP_STATUS_CODE_500: {'message': 'Internal Server Error.', 'code': 500} [in /home/quynt13/Desktop/ACBank/agentstats-api/app/exceptions.py:191]
Traceback (most recent call last):
  File "/usr/local/lib/python2.7/dist-packages/flask/app.py", line 1612, in full_dispatch_request
    rv = self.dispatch_request()
  File "/usr/local/lib/python2.7/dist-packages/flask/app.py", line 1598, in dispatch_request
    return self.view_functions[rule.endpoint](**req.view_args)
  File "/home/quynt13/Desktop/ACBank/agentstats-api/app/api/minion.py", line 81, in list_minions
    return jsonify(result)
  File "/usr/local/lib/python2.7/dist-packages/flask/json.py", line 263, in jsonify
    (dumps(data, indent=indent, separators=separators), '\n'),
  File "/usr/local/lib/python2.7/dist-packages/flask/json.py", line 123, in dumps
    rv = _json.dumps(obj, **kwargs)
  File "/usr/lib/python2.7/json/__init__.py", line 250, in dumps
    sort_keys=sort_keys, **kw).encode(obj)
  File "/usr/lib/python2.7/json/encoder.py", line 209, in encode
    chunks = list(chunks)
  File "/usr/lib/python2.7/json/encoder.py", line 434, in _iterencode
    for chunk in _iterencode_dict(o, _current_indent_level):
  File "/usr/lib/python2.7/json/encoder.py", line 408, in _iterencode_dict
    for chunk in chunks:
  File "/usr/lib/python2.7/json/encoder.py", line 332, in _iterencode_list
    for chunk in chunks:
  File "/usr/lib/python2.7/json/encoder.py", line 408, in _iterencode_dict
    for chunk in chunks:
  File "/usr/lib/python2.7/json/encoder.py", line 442, in _iterencode
    o = _default(o)
  File "/usr/local/lib/python2.7/dist-packages/flask/json.py", line 80, in default
    return _json.JSONEncoder.default(self, o)
  File "/usr/lib/python2.7/json/encoder.py", line 184, in default
    raise TypeError(repr(o) + " is not JSON serializable")
TypeError: ObjectId('5916c0b5fdbcfc37a0155020') is not JSON serializable
2017-11-10 08:00:22,842 ERROR: HTTP_STATUS_CODE_500: {'message': 'Internal Server Error.', 'code': 500} [in /home/quynt13/Desktop/ACBank/agentstats-api/app/exceptions.py:191]
Traceback (most recent call last):
  File "/usr/local/lib/python2.7/dist-packages/flask/app.py", line 1612, in full_dispatch_request
    rv = self.dispatch_request()
  File "/usr/local/lib/python2.7/dist-packages/flask/app.py", line 1598, in dispatch_request
    return self.view_functions[rule.endpoint](**req.view_args)
  File "/home/quynt13/Desktop/ACBank/agentstats-api/app/api/minion.py", line 81, in list_minions
    return jsonify(result)
  File "/usr/local/lib/python2.7/dist-packages/flask/json.py", line 263, in jsonify
    (dumps(data, indent=indent, separators=separators), '\n'),
  File "/usr/local/lib/python2.7/dist-packages/flask/json.py", line 123, in dumps
    rv = _json.dumps(obj, **kwargs)
  File "/usr/lib/python2.7/json/__init__.py", line 250, in dumps
    sort_keys=sort_keys, **kw).encode(obj)
  File "/usr/lib/python2.7/json/encoder.py", line 209, in encode
    chunks = list(chunks)
  File "/usr/lib/python2.7/json/encoder.py", line 434, in _iterencode
    for chunk in _iterencode_dict(o, _current_indent_level):
  File "/usr/lib/python2.7/json/encoder.py", line 408, in _iterencode_dict
    for chunk in chunks:
  File "/usr/lib/python2.7/json/encoder.py", line 332, in _iterencode_list
    for chunk in chunks:
  File "/usr/lib/python2.7/json/encoder.py", line 408, in _iterencode_dict
    for chunk in chunks:
  File "/usr/lib/python2.7/json/encoder.py", line 442, in _iterencode
    o = _default(o)
  File "/usr/local/lib/python2.7/dist-packages/flask/json.py", line 80, in default
    return _json.JSONEncoder.default(self, o)
  File "/usr/lib/python2.7/json/encoder.py", line 184, in default
    raise TypeError(repr(o) + " is not JSON serializable")
TypeError: ObjectId('5916c0b5fdbcfc37a0155020') is not JSON serializable
2017-11-10 08:02:33,009 ERROR: HTTP_STATUS_CODE_500: {'message': 'Internal Server Error.', 'code': 500} [in /home/quynt13/Desktop/ACBank/agentstats-api/app/exceptions.py:191]
Traceback (most recent call last):
  File "/usr/local/lib/python2.7/dist-packages/flask/app.py", line 1612, in full_dispatch_request
    rv = self.dispatch_request()
  File "/usr/local/lib/python2.7/dist-packages/flask/app.py", line 1598, in dispatch_request
    return self.view_functions[rule.endpoint](**req.view_args)
  File "/home/quynt13/Desktop/ACBank/agentstats-api/app/api/minion.py", line 81, in list_minions
    return jsonify(result)
  File "/usr/local/lib/python2.7/dist-packages/flask/json.py", line 263, in jsonify
    (dumps(data, indent=indent, separators=separators), '\n'),
  File "/usr/local/lib/python2.7/dist-packages/flask/json.py", line 123, in dumps
    rv = _json.dumps(obj, **kwargs)
  File "/usr/lib/python2.7/json/__init__.py", line 250, in dumps
    sort_keys=sort_keys, **kw).encode(obj)
  File "/usr/lib/python2.7/json/encoder.py", line 209, in encode
    chunks = list(chunks)
  File "/usr/lib/python2.7/json/encoder.py", line 434, in _iterencode
    for chunk in _iterencode_dict(o, _current_indent_level):
  File "/usr/lib/python2.7/json/encoder.py", line 408, in _iterencode_dict
    for chunk in chunks:
  File "/usr/lib/python2.7/json/encoder.py", line 332, in _iterencode_list
    for chunk in chunks:
  File "/usr/lib/python2.7/json/encoder.py", line 408, in _iterencode_dict
    for chunk in chunks:
  File "/usr/lib/python2.7/json/encoder.py", line 442, in _iterencode
    o = _default(o)
  File "/usr/local/lib/python2.7/dist-packages/flask/json.py", line 80, in default
    return _json.JSONEncoder.default(self, o)
  File "/usr/lib/python2.7/json/encoder.py", line 184, in default
    raise TypeError(repr(o) + " is not JSON serializable")
TypeError: ObjectId('5916c0b5fdbcfc37a0155020') is not JSON serializable
2017-11-10 08:05:25,526 ERROR: HTTP_STATUS_CODE_500: {'message': 'Internal Server Error.', 'code': 500} [in /home/quynt13/Desktop/ACBank/agentstats-api/app/exceptions.py:191]
Traceback (most recent call last):
  File "/usr/local/lib/python2.7/dist-packages/flask/app.py", line 1612, in full_dispatch_request
    rv = self.dispatch_request()
  File "/usr/local/lib/python2.7/dist-packages/flask/app.py", line 1598, in dispatch_request
    return self.view_functions[rule.endpoint](**req.view_args)
  File "/home/quynt13/Desktop/ACBank/agentstats-api/app/api/minion.py", line 81, in list_minions
    return jsonify(result)
  File "/usr/local/lib/python2.7/dist-packages/flask/json.py", line 263, in jsonify
    (dumps(data, indent=indent, separators=separators), '\n'),
  File "/usr/local/lib/python2.7/dist-packages/flask/json.py", line 123, in dumps
    rv = _json.dumps(obj, **kwargs)
  File "/usr/lib/python2.7/json/__init__.py", line 250, in dumps
    sort_keys=sort_keys, **kw).encode(obj)
  File "/usr/lib/python2.7/json/encoder.py", line 209, in encode
    chunks = list(chunks)
  File "/usr/lib/python2.7/json/encoder.py", line 434, in _iterencode
    for chunk in _iterencode_dict(o, _current_indent_level):
  File "/usr/lib/python2.7/json/encoder.py", line 408, in _iterencode_dict
    for chunk in chunks:
  File "/usr/lib/python2.7/json/encoder.py", line 332, in _iterencode_list
    for chunk in chunks:
  File "/usr/lib/python2.7/json/encoder.py", line 408, in _iterencode_dict
    for chunk in chunks:
  File "/usr/lib/python2.7/json/encoder.py", line 442, in _iterencode
    o = _default(o)
  File "/usr/local/lib/python2.7/dist-packages/flask/json.py", line 80, in default
    return _json.JSONEncoder.default(self, o)
  File "/usr/lib/python2.7/json/encoder.py", line 184, in default
    raise TypeError(repr(o) + " is not JSON serializable")
TypeError: ObjectId('5916c0b5fdbcfc37a0155020') is not JSON serializable
2017-11-10 08:05:47,100 ERROR: HTTP_STATUS_CODE_500: {'message': 'Internal Server Error.', 'code': 500} [in /home/quynt13/Desktop/ACBank/agentstats-api/app/exceptions.py:191]
Traceback (most recent call last):
  File "/usr/local/lib/python2.7/dist-packages/flask/app.py", line 1612, in full_dispatch_request
    rv = self.dispatch_request()
  File "/usr/local/lib/python2.7/dist-packages/flask/app.py", line 1598, in dispatch_request
    return self.view_functions[rule.endpoint](**req.view_args)
  File "/home/quynt13/Desktop/ACBank/agentstats-api/app/api/minion.py", line 81, in list_minions
    return jsonify(result)
  File "/usr/local/lib/python2.7/dist-packages/flask/json.py", line 263, in jsonify
    (dumps(data, indent=indent, separators=separators), '\n'),
  File "/usr/local/lib/python2.7/dist-packages/flask/json.py", line 123, in dumps
    rv = _json.dumps(obj, **kwargs)
  File "/usr/lib/python2.7/json/__init__.py", line 250, in dumps
    sort_keys=sort_keys, **kw).encode(obj)
  File "/usr/lib/python2.7/json/encoder.py", line 209, in encode
    chunks = list(chunks)
  File "/usr/lib/python2.7/json/encoder.py", line 434, in _iterencode
    for chunk in _iterencode_dict(o, _current_indent_level):
  File "/usr/lib/python2.7/json/encoder.py", line 408, in _iterencode_dict
    for chunk in chunks:
  File "/usr/lib/python2.7/json/encoder.py", line 332, in _iterencode_list
    for chunk in chunks:
  File "/usr/lib/python2.7/json/encoder.py", line 408, in _iterencode_dict
    for chunk in chunks:
  File "/usr/lib/python2.7/json/encoder.py", line 442, in _iterencode
    o = _default(o)
  File "/usr/local/lib/python2.7/dist-packages/flask/json.py", line 80, in default
    return _json.JSONEncoder.default(self, o)
  File "/usr/lib/python2.7/json/encoder.py", line 184, in default
    raise TypeError(repr(o) + " is not JSON serializable")
TypeError: ObjectId('5916c0b5fdbcfc37a0155020') is not JSON serializable
2017-11-10 08:08:34,295 INFO: Config filename: app/config.py [in /home/quynt13/Desktop/ACBank/agentstats-api/app/app.py:107]
2017-11-10 08:08:34,295 INFO: App log folder: /home/quynt13/Desktop/ACBank/agentstats-api/logs [in /home/quynt13/Desktop/ACBank/agentstats-api/app/app.py:108]
2017-11-10 08:08:40,745 ERROR: HTTP_STATUS_CODE_500: {'message': 'Internal Server Error.', 'code': 500} [in /home/quynt13/Desktop/ACBank/agentstats-api/app/exceptions.py:191]
Traceback (most recent call last):
  File "/usr/local/lib/python2.7/dist-packages/flask/app.py", line 1612, in full_dispatch_request
    rv = self.dispatch_request()
  File "/usr/local/lib/python2.7/dist-packages/flask/app.py", line 1598, in dispatch_request
    return self.view_functions[rule.endpoint](**req.view_args)
  File "/home/quynt13/Desktop/ACBank/agentstats-api/app/api/minion.py", line 81, in list_minions
    return jsonify(result)
  File "/usr/local/lib/python2.7/dist-packages/flask/json.py", line 263, in jsonify
    (dumps(data, indent=indent, separators=separators), '\n'),
  File "/usr/local/lib/python2.7/dist-packages/flask/json.py", line 123, in dumps
    rv = _json.dumps(obj, **kwargs)
  File "/usr/lib/python2.7/json/__init__.py", line 250, in dumps
    sort_keys=sort_keys, **kw).encode(obj)
  File "/usr/lib/python2.7/json/encoder.py", line 209, in encode
    chunks = list(chunks)
  File "/usr/lib/python2.7/json/encoder.py", line 434, in _iterencode
    for chunk in _iterencode_dict(o, _current_indent_level):
  File "/usr/lib/python2.7/json/encoder.py", line 408, in _iterencode_dict
    for chunk in chunks:
  File "/usr/lib/python2.7/json/encoder.py", line 332, in _iterencode_list
    for chunk in chunks:
  File "/usr/lib/python2.7/json/encoder.py", line 408, in _iterencode_dict
    for chunk in chunks:
  File "/usr/lib/python2.7/json/encoder.py", line 442, in _iterencode
    o = _default(o)
  File "/usr/local/lib/python2.7/dist-packages/flask/json.py", line 80, in default
    return _json.JSONEncoder.default(self, o)
  File "/usr/lib/python2.7/json/encoder.py", line 184, in default
    raise TypeError(repr(o) + " is not JSON serializable")
TypeError: ObjectId('5916c0b5fdbcfc37a0155020') is not JSON serializable
2017-11-10 08:08:43,381 INFO: Config filename: app/config.py [in /home/quynt13/Desktop/ACBank/agentstats-api/app/app.py:107]
2017-11-10 08:08:43,381 INFO: App log folder: /home/quynt13/Desktop/ACBank/agentstats-api/logs [in /home/quynt13/Desktop/ACBank/agentstats-api/app/app.py:108]
2017-11-10 08:08:51,451 ERROR: HTTP_STATUS_CODE_500: {'message': 'Internal Server Error.', 'code': 500} [in /home/quynt13/Desktop/ACBank/agentstats-api/app/exceptions.py:191]
Traceback (most recent call last):
  File "/usr/local/lib/python2.7/dist-packages/flask/app.py", line 1612, in full_dispatch_request
    rv = self.dispatch_request()
  File "/usr/local/lib/python2.7/dist-packages/flask/app.py", line 1598, in dispatch_request
    return self.view_functions[rule.endpoint](**req.view_args)
  File "/home/quynt13/Desktop/ACBank/agentstats-api/app/api/minion.py", line 81, in list_minions
    return jsonify(result)
  File "/usr/local/lib/python2.7/dist-packages/flask/json.py", line 263, in jsonify
    (dumps(data, indent=indent, separators=separators), '\n'),
  File "/usr/local/lib/python2.7/dist-packages/flask/json.py", line 123, in dumps
    rv = _json.dumps(obj, **kwargs)
  File "/usr/lib/python2.7/json/__init__.py", line 250, in dumps
    sort_keys=sort_keys, **kw).encode(obj)
  File "/usr/lib/python2.7/json/encoder.py", line 209, in encode
    chunks = list(chunks)
  File "/usr/lib/python2.7/json/encoder.py", line 434, in _iterencode
    for chunk in _iterencode_dict(o, _current_indent_level):
  File "/usr/lib/python2.7/json/encoder.py", line 408, in _iterencode_dict
    for chunk in chunks:
  File "/usr/lib/python2.7/json/encoder.py", line 332, in _iterencode_list
    for chunk in chunks:
  File "/usr/lib/python2.7/json/encoder.py", line 408, in _iterencode_dict
    for chunk in chunks:
  File "/usr/lib/python2.7/json/encoder.py", line 442, in _iterencode
    o = _default(o)
  File "/usr/local/lib/python2.7/dist-packages/flask/json.py", line 80, in default
    return _json.JSONEncoder.default(self, o)
  File "/usr/lib/python2.7/json/encoder.py", line 184, in default
    raise TypeError(repr(o) + " is not JSON serializable")
TypeError: ObjectId('5916c0b5fdbcfc37a0155020') is not JSON serializable
2017-11-10 08:09:13,974 INFO: Config filename: app/config.py [in /home/quynt13/Desktop/ACBank/agentstats-api/app/app.py:107]
2017-11-10 08:09:13,974 INFO: App log folder: /home/quynt13/Desktop/ACBank/agentstats-api/logs [in /home/quynt13/Desktop/ACBank/agentstats-api/app/app.py:108]
2017-11-10 08:09:22,694 ERROR: HTTP_STATUS_CODE_500: {'message': 'Internal Server Error.', 'code': 500} [in /home/quynt13/Desktop/ACBank/agentstats-api/app/exceptions.py:191]
Traceback (most recent call last):
  File "/usr/local/lib/python2.7/dist-packages/flask/app.py", line 1612, in full_dispatch_request
    rv = self.dispatch_request()
  File "/usr/local/lib/python2.7/dist-packages/flask/app.py", line 1598, in dispatch_request
    return self.view_functions[rule.endpoint](**req.view_args)
  File "/home/quynt13/Desktop/ACBank/agentstats-api/app/api/minion.py", line 81, in list_minions
    return jsonify(result)
  File "/usr/local/lib/python2.7/dist-packages/flask/json.py", line 263, in jsonify
    (dumps(data, indent=indent, separators=separators), '\n'),
  File "/usr/local/lib/python2.7/dist-packages/flask/json.py", line 123, in dumps
    rv = _json.dumps(obj, **kwargs)
  File "/usr/lib/python2.7/json/__init__.py", line 250, in dumps
    sort_keys=sort_keys, **kw).encode(obj)
  File "/usr/lib/python2.7/json/encoder.py", line 209, in encode
    chunks = list(chunks)
  File "/usr/lib/python2.7/json/encoder.py", line 434, in _iterencode
    for chunk in _iterencode_dict(o, _current_indent_level):
  File "/usr/lib/python2.7/json/encoder.py", line 408, in _iterencode_dict
    for chunk in chunks:
  File "/usr/lib/python2.7/json/encoder.py", line 332, in _iterencode_list
    for chunk in chunks:
  File "/usr/lib/python2.7/json/encoder.py", line 408, in _iterencode_dict
    for chunk in chunks:
  File "/usr/lib/python2.7/json/encoder.py", line 442, in _iterencode
    o = _default(o)
  File "/usr/local/lib/python2.7/dist-packages/flask/json.py", line 80, in default
    return _json.JSONEncoder.default(self, o)
  File "/usr/lib/python2.7/json/encoder.py", line 184, in default
    raise TypeError(repr(o) + " is not JSON serializable")
TypeError: ObjectId('5916c0b5fdbcfc37a0155020') is not JSON serializable
2017-11-10 08:09:29,636 ERROR: HTTP_STATUS_CODE_500: {'message': 'Internal Server Error.', 'code': 500} [in /home/quynt13/Desktop/ACBank/agentstats-api/app/exceptions.py:191]
Traceback (most recent call last):
  File "/usr/local/lib/python2.7/dist-packages/flask/app.py", line 1612, in full_dispatch_request
    rv = self.dispatch_request()
  File "/usr/local/lib/python2.7/dist-packages/flask/app.py", line 1598, in dispatch_request
    return self.view_functions[rule.endpoint](**req.view_args)
  File "/home/quynt13/Desktop/ACBank/agentstats-api/app/api/minion.py", line 81, in list_minions
    return jsonify(result)
  File "/usr/local/lib/python2.7/dist-packages/flask/json.py", line 263, in jsonify
    (dumps(data, indent=indent, separators=separators), '\n'),
  File "/usr/local/lib/python2.7/dist-packages/flask/json.py", line 123, in dumps
    rv = _json.dumps(obj, **kwargs)
  File "/usr/lib/python2.7/json/__init__.py", line 250, in dumps
    sort_keys=sort_keys, **kw).encode(obj)
  File "/usr/lib/python2.7/json/encoder.py", line 209, in encode
    chunks = list(chunks)
  File "/usr/lib/python2.7/json/encoder.py", line 434, in _iterencode
    for chunk in _iterencode_dict(o, _current_indent_level):
  File "/usr/lib/python2.7/json/encoder.py", line 408, in _iterencode_dict
    for chunk in chunks:
  File "/usr/lib/python2.7/json/encoder.py", line 332, in _iterencode_list
    for chunk in chunks:
  File "/usr/lib/python2.7/json/encoder.py", line 408, in _iterencode_dict
    for chunk in chunks:
  File "/usr/lib/python2.7/json/encoder.py", line 442, in _iterencode
    o = _default(o)
  File "/usr/local/lib/python2.7/dist-packages/flask/json.py", line 80, in default
    return _json.JSONEncoder.default(self, o)
  File "/usr/lib/python2.7/json/encoder.py", line 184, in default
    raise TypeError(repr(o) + " is not JSON serializable")
TypeError: ObjectId('5916c0b5fdbcfc37a0155020') is not JSON serializable
2017-11-10 08:11:34,487 INFO: Config filename: app/config.py [in /home/quynt13/Desktop/ACBank/agentstats-api/app/app.py:107]
2017-11-10 08:11:34,487 INFO: App log folder: /home/quynt13/Desktop/ACBank/agentstats-api/logs [in /home/quynt13/Desktop/ACBank/agentstats-api/app/app.py:108]
2017-11-10 08:11:56,227 INFO: Config filename: app/config.py [in /home/quynt13/Desktop/ACBank/agentstats-api/app/app.py:107]
2017-11-10 08:11:56,227 INFO: App log folder: /home/quynt13/Desktop/ACBank/agentstats-api/logs [in /home/quynt13/Desktop/ACBank/agentstats-api/app/app.py:108]
2017-11-10 08:12:30,159 INFO: Config filename: app/config.py [in /home/quynt13/Desktop/ACBank/agentstats-api/app/app.py:107]
2017-11-10 08:12:30,173 INFO: App log folder: /home/quynt13/Desktop/ACBank/agentstats-api/logs [in /home/quynt13/Desktop/ACBank/agentstats-api/app/app.py:108]
2017-11-10 08:13:45,293 INFO: Config filename: app/config.py [in /home/quynt13/Desktop/ACBank/agentstats-api/app/app.py:107]
2017-11-10 08:13:45,298 INFO: App log folder: /home/quynt13/Desktop/ACBank/agentstats-api/logs [in /home/quynt13/Desktop/ACBank/agentstats-api/app/app.py:108]
2017-11-10 08:28:23,361 INFO: Config filename: app/config.py [in /home/quynt13/Desktop/ACBank/agentstats-api/app/app.py:109]
2017-11-10 08:28:23,361 INFO: App log folder: /home/quynt13/Desktop/ACBank/agentstats-api/logs [in /home/quynt13/Desktop/ACBank/agentstats-api/app/app.py:110]
2017-11-10 08:29:15,251 INFO: Config filename: app/config.py [in /home/quynt13/Desktop/ACBank/agentstats-api/app/app.py:109]
2017-11-10 08:29:15,251 INFO: App log folder: /home/quynt13/Desktop/ACBank/agentstats-api/logs [in /home/quynt13/Desktop/ACBank/agentstats-api/app/app.py:110]
2017-11-10 08:29:43,295 ERROR: HTTP_STATUS_CODE_500: {'message': 'Internal Server Error.', 'code': 500} [in /home/quynt13/Desktop/ACBank/agentstats-api/app/exceptions.py:191]
Traceback (most recent call last):
  File "/usr/local/lib/python2.7/dist-packages/flask/app.py", line 1612, in full_dispatch_request
    rv = self.dispatch_request()
  File "/usr/local/lib/python2.7/dist-packages/flask/app.py", line 1598, in dispatch_request
    return self.view_functions[rule.endpoint](**req.view_args)
  File "/usr/local/lib/python2.7/dist-packages/flask_oauth2/resources/__init__.py", line 37, in decorated
    return f(*args, **kwargs)
  File "/usr/local/lib/python2.7/dist-packages/flask_permissions/permissions/__init__.py", line 57, in decorated
    return f(*args, **kwargs)
  File "/home/quynt13/Desktop/ACBank/agentstats-api/app/api/account.py", line 96, in view_account
    'account_number': args['account_number'],
KeyError: 'account_number'
2017-11-10 08:31:50,496 INFO: Config filename: app/config.py [in /home/quynt13/Desktop/ACBank/agentstats-api/app/app.py:109]
2017-11-10 08:31:50,497 INFO: App log folder: /home/quynt13/Desktop/ACBank/agentstats-api/logs [in /home/quynt13/Desktop/ACBank/agentstats-api/app/app.py:110]
2017-11-10 08:35:58,357 ERROR: HTTP_STATUS_CODE_405: {'message': 'Method Not Allowed.', 'code': 405} [in /home/quynt13/Desktop/ACBank/agentstats-api/app/exceptions.py:191]
Traceback (most recent call last):
  File "/usr/local/lib/python2.7/dist-packages/flask/app.py", line 1612, in full_dispatch_request
    rv = self.dispatch_request()
  File "/usr/local/lib/python2.7/dist-packages/flask/app.py", line 1590, in dispatch_request
    self.raise_routing_exception(req)
  File "/usr/local/lib/python2.7/dist-packages/flask/app.py", line 1573, in raise_routing_exception
    raise request.routing_exception
MethodNotAllowed: 405 Method Not Allowed: {'message': 'Method Not Allowed.', 'code': 405}
2017-11-10 08:39:27,802 ERROR: HTTP_STATUS_CODE_405: {'message': 'Method Not Allowed.', 'code': 405} [in /home/quynt13/Desktop/ACBank/agentstats-api/app/exceptions.py:191]
Traceback (most recent call last):
  File "/usr/local/lib/python2.7/dist-packages/flask/app.py", line 1612, in full_dispatch_request
    rv = self.dispatch_request()
  File "/usr/local/lib/python2.7/dist-packages/flask/app.py", line 1590, in dispatch_request
    self.raise_routing_exception(req)
  File "/usr/local/lib/python2.7/dist-packages/flask/app.py", line 1573, in raise_routing_exception
    raise request.routing_exception
MethodNotAllowed: 405 Method Not Allowed: {'message': 'Method Not Allowed.', 'code': 405}
2017-11-10 08:39:33,360 ERROR: HTTP_STATUS_CODE_422: {'message': 'Validation error, re-check your data.', 'code': 422} [in /home/quynt13/Desktop/ACBank/agentstats-api/app/exceptions.py:191]
Traceback (most recent call last):
  File "/usr/local/lib/python2.7/dist-packages/flask/app.py", line 1612, in full_dispatch_request
    rv = self.dispatch_request()
  File "/usr/local/lib/python2.7/dist-packages/flask/app.py", line 1598, in dispatch_request
    return self.view_functions[rule.endpoint](**req.view_args)
  File "/home/quynt13/Desktop/ACBank/agentstats-api/app/api/minion.py", line 39, in list_minions
    args = parser.parse(params)
  File "/usr/local/lib/python2.7/dist-packages/webargs/core.py", line 363, in parse
    self._on_validation_error(error)
  File "/usr/local/lib/python2.7/dist-packages/webargs/core.py", line 310, in _on_validation_error
    self.handle_error(error)
  File "/usr/local/lib/python2.7/dist-packages/webargs/flaskparser.py", line 105, in handle_error
    abort(status_code, messages=error.messages, exc=error)
  File "/usr/local/lib/python2.7/dist-packages/webargs/flaskparser.py", line 40, in abort
    raise err
UnprocessableEntity: 422 Unprocessable Entity: {'message': 'Validation error, re-check your data.', 'code': 422}
2017-11-10 08:44:06,333 INFO: Config filename: app/config.py [in /home/quynt13/Desktop/ACBank/agentstats-api/app/app.py:109]
2017-11-10 08:44:06,334 INFO: App log folder: /home/quynt13/Desktop/ACBank/agentstats-api/logs [in /home/quynt13/Desktop/ACBank/agentstats-api/app/app.py:110]
2017-11-10 08:44:29,975 ERROR: HTTP_STATUS_CODE_422: {'message': 'Validation error, re-check your data.', 'code': 422} [in /home/quynt13/Desktop/ACBank/agentstats-api/app/exceptions.py:191]
Traceback (most recent call last):
  File "/usr/local/lib/python2.7/dist-packages/flask/app.py", line 1612, in full_dispatch_request
    rv = self.dispatch_request()
  File "/usr/local/lib/python2.7/dist-packages/flask/app.py", line 1598, in dispatch_request
    return self.view_functions[rule.endpoint](**req.view_args)
  File "/usr/local/lib/python2.7/dist-packages/flask_oauth2/resources/__init__.py", line 37, in decorated
    return f(*args, **kwargs)
  File "/usr/local/lib/python2.7/dist-packages/flask_permissions/permissions/__init__.py", line 57, in decorated
    return f(*args, **kwargs)
  File "/home/quynt13/Desktop/ACBank/agentstats-api/app/api/minion.py", line 39, in list_minions
    args = parser.parse(params)
  File "/usr/local/lib/python2.7/dist-packages/webargs/core.py", line 363, in parse
    self._on_validation_error(error)
  File "/usr/local/lib/python2.7/dist-packages/webargs/core.py", line 310, in _on_validation_error
    self.handle_error(error)
  File "/usr/local/lib/python2.7/dist-packages/webargs/flaskparser.py", line 105, in handle_error
    abort(status_code, messages=error.messages, exc=error)
  File "/usr/local/lib/python2.7/dist-packages/webargs/flaskparser.py", line 40, in abort
    raise err
UnprocessableEntity: 422 Unprocessable Entity: {'message': 'Validation error, re-check your data.', 'code': 422}
2017-11-10 08:44:54,733 INFO: Config filename: app/config.py [in /home/quynt13/Desktop/ACBank/agentstats-api/app/app.py:109]
2017-11-10 08:44:54,734 INFO: App log folder: /home/quynt13/Desktop/ACBank/agentstats-api/logs [in /home/quynt13/Desktop/ACBank/agentstats-api/app/app.py:110]
2017-11-10 08:45:29,684 ERROR: HTTP_STATUS_CODE_422: {'message': 'Validation error, re-check your data.', 'code': 422} [in /home/quynt13/Desktop/ACBank/agentstats-api/app/exceptions.py:191]
Traceback (most recent call last):
  File "/usr/local/lib/python2.7/dist-packages/flask/app.py", line 1612, in full_dispatch_request
    rv = self.dispatch_request()
  File "/usr/local/lib/python2.7/dist-packages/flask/app.py", line 1598, in dispatch_request
    return self.view_functions[rule.endpoint](**req.view_args)
  File "/usr/local/lib/python2.7/dist-packages/flask_oauth2/resources/__init__.py", line 37, in decorated
    return f(*args, **kwargs)
  File "/usr/local/lib/python2.7/dist-packages/flask_permissions/permissions/__init__.py", line 57, in decorated
    return f(*args, **kwargs)
  File "/home/quynt13/Desktop/ACBank/agentstats-api/app/api/minion.py", line 39, in list_minions
    args = parser.parse(params)
  File "/usr/local/lib/python2.7/dist-packages/webargs/core.py", line 363, in parse
    self._on_validation_error(error)
  File "/usr/local/lib/python2.7/dist-packages/webargs/core.py", line 310, in _on_validation_error
    self.handle_error(error)
  File "/usr/local/lib/python2.7/dist-packages/webargs/flaskparser.py", line 105, in handle_error
    abort(status_code, messages=error.messages, exc=error)
  File "/usr/local/lib/python2.7/dist-packages/webargs/flaskparser.py", line 40, in abort
    raise err
UnprocessableEntity: 422 Unprocessable Entity: {'message': 'Validation error, re-check your data.', 'code': 422}
2017-11-10 08:46:45,573 INFO: Config filename: app/config.py [in /home/quynt13/Desktop/ACBank/agentstats-api/app/app.py:109]
2017-11-10 08:46:45,574 INFO: App log folder: /home/quynt13/Desktop/ACBank/agentstats-api/logs [in /home/quynt13/Desktop/ACBank/agentstats-api/app/app.py:110]
2017-11-10 08:48:03,250 INFO: Config filename: app/config.py [in /home/quynt13/Desktop/ACBank/agentstats-api/app/app.py:109]
2017-11-10 08:48:03,251 INFO: App log folder: /home/quynt13/Desktop/ACBank/agentstats-api/logs [in /home/quynt13/Desktop/ACBank/agentstats-api/app/app.py:110]
2017-11-10 08:48:08,471 INFO: Config filename: app/config.py [in /home/quynt13/Desktop/ACBank/agentstats-api/app/app.py:109]
2017-11-10 08:48:08,471 INFO: App log folder: /home/quynt13/Desktop/ACBank/agentstats-api/logs [in /home/quynt13/Desktop/ACBank/agentstats-api/app/app.py:110]
2017-11-10 08:48:20,921 ERROR: HTTP_STATUS_CODE_422: {'message': 'Validation error, re-check your data.', 'code': 422} [in /home/quynt13/Desktop/ACBank/agentstats-api/app/exceptions.py:191]
Traceback (most recent call last):
  File "/usr/local/lib/python2.7/dist-packages/flask/app.py", line 1612, in full_dispatch_request
    rv = self.dispatch_request()
  File "/usr/local/lib/python2.7/dist-packages/flask/app.py", line 1598, in dispatch_request
    return self.view_functions[rule.endpoint](**req.view_args)
  File "/home/quynt13/Desktop/ACBank/agentstats-api/app/api/minion.py", line 39, in list_minions
    args = parser.parse(params)
  File "/usr/local/lib/python2.7/dist-packages/webargs/core.py", line 363, in parse
    self._on_validation_error(error)
  File "/usr/local/lib/python2.7/dist-packages/webargs/core.py", line 310, in _on_validation_error
    self.handle_error(error)
  File "/usr/local/lib/python2.7/dist-packages/webargs/flaskparser.py", line 105, in handle_error
    abort(status_code, messages=error.messages, exc=error)
  File "/usr/local/lib/python2.7/dist-packages/webargs/flaskparser.py", line 40, in abort
    raise err
UnprocessableEntity: 422 Unprocessable Entity: {'message': 'Validation error, re-check your data.', 'code': 422}
2017-11-10 08:51:42,022 INFO: Config filename: app/config.py [in /home/quynt13/Desktop/ACBank/agentstats-api/app/app.py:109]
2017-11-10 08:51:42,022 INFO: App log folder: /home/quynt13/Desktop/ACBank/agentstats-api/logs [in /home/quynt13/Desktop/ACBank/agentstats-api/app/app.py:110]
2017-11-10 08:53:27,337 INFO: Config filename: app/config.py [in /home/quynt13/Desktop/ACBank/agentstats-api/app/app.py:109]
2017-11-10 08:53:27,338 INFO: App log folder: /home/quynt13/Desktop/ACBank/agentstats-api/logs [in /home/quynt13/Desktop/ACBank/agentstats-api/app/app.py:110]
2017-11-10 08:53:32,431 INFO: Config filename: app/config.py [in /home/quynt13/Desktop/ACBank/agentstats-api/app/app.py:109]
2017-11-10 08:53:32,431 INFO: App log folder: /home/quynt13/Desktop/ACBank/agentstats-api/logs [in /home/quynt13/Desktop/ACBank/agentstats-api/app/app.py:110]
2017-11-10 08:53:41,318 ERROR: HTTP_STATUS_CODE_422: {'message': 'Validation error, re-check your data.', 'code': 422} [in /home/quynt13/Desktop/ACBank/agentstats-api/app/exceptions.py:191]
Traceback (most recent call last):
  File "/usr/local/lib/python2.7/dist-packages/flask/app.py", line 1612, in full_dispatch_request
    rv = self.dispatch_request()
  File "/usr/local/lib/python2.7/dist-packages/flask/app.py", line 1598, in dispatch_request
    return self.view_functions[rule.endpoint](**req.view_args)
  File "/home/quynt13/Desktop/ACBank/agentstats-api/app/api/minion.py", line 39, in list_minions
    args = parser.parse(params)
  File "/usr/local/lib/python2.7/dist-packages/webargs/core.py", line 363, in parse
    self._on_validation_error(error)
  File "/usr/local/lib/python2.7/dist-packages/webargs/core.py", line 310, in _on_validation_error
    self.handle_error(error)
  File "/usr/local/lib/python2.7/dist-packages/webargs/flaskparser.py", line 105, in handle_error
    abort(status_code, messages=error.messages, exc=error)
  File "/usr/local/lib/python2.7/dist-packages/webargs/flaskparser.py", line 40, in abort
    raise err
UnprocessableEntity: 422 Unprocessable Entity: {'message': 'Validation error, re-check your data.', 'code': 422}
2017-11-10 08:54:17,694 INFO: Config filename: app/config.py [in /home/quynt13/Desktop/ACBank/agentstats-api/app/app.py:109]
2017-11-10 08:54:17,694 INFO: App log folder: /home/quynt13/Desktop/ACBank/agentstats-api/logs [in /home/quynt13/Desktop/ACBank/agentstats-api/app/app.py:110]
2017-11-10 08:54:23,156 INFO: Config filename: app/config.py [in /home/quynt13/Desktop/ACBank/agentstats-api/app/app.py:109]
2017-11-10 08:54:23,156 INFO: App log folder: /home/quynt13/Desktop/ACBank/agentstats-api/logs [in /home/quynt13/Desktop/ACBank/agentstats-api/app/app.py:110]
2017-11-10 08:54:41,931 ERROR: HTTP_STATUS_CODE_422: {'message': 'Validation error, re-check your data.', 'code': 422} [in /home/quynt13/Desktop/ACBank/agentstats-api/app/exceptions.py:191]
Traceback (most recent call last):
  File "/usr/local/lib/python2.7/dist-packages/flask/app.py", line 1612, in full_dispatch_request
    rv = self.dispatch_request()
  File "/usr/local/lib/python2.7/dist-packages/flask/app.py", line 1598, in dispatch_request
    return self.view_functions[rule.endpoint](**req.view_args)
  File "/usr/local/lib/python2.7/dist-packages/flask_oauth2/resources/__init__.py", line 37, in decorated
    return f(*args, **kwargs)
  File "/usr/local/lib/python2.7/dist-packages/flask_permissions/permissions/__init__.py", line 57, in decorated
    return f(*args, **kwargs)
  File "/home/quynt13/Desktop/ACBank/agentstats-api/app/api/account.py", line 35, in list_accounts
    args = parser.parse(params)
  File "/usr/local/lib/python2.7/dist-packages/webargs/core.py", line 363, in parse
    self._on_validation_error(error)
  File "/usr/local/lib/python2.7/dist-packages/webargs/core.py", line 310, in _on_validation_error
    self.handle_error(error)
  File "/usr/local/lib/python2.7/dist-packages/webargs/flaskparser.py", line 105, in handle_error
    abort(status_code, messages=error.messages, exc=error)
  File "/usr/local/lib/python2.7/dist-packages/webargs/flaskparser.py", line 40, in abort
    raise err
UnprocessableEntity: 422 Unprocessable Entity: {'message': 'Validation error, re-check your data.', 'code': 422}
2017-11-10 08:54:46,714 ERROR: HTTP_STATUS_CODE_422: {'message': 'Validation error, re-check your data.', 'code': 422} [in /home/quynt13/Desktop/ACBank/agentstats-api/app/exceptions.py:191]
Traceback (most recent call last):
  File "/usr/local/lib/python2.7/dist-packages/flask/app.py", line 1612, in full_dispatch_request
    rv = self.dispatch_request()
  File "/usr/local/lib/python2.7/dist-packages/flask/app.py", line 1598, in dispatch_request
    return self.view_functions[rule.endpoint](**req.view_args)
  File "/usr/local/lib/python2.7/dist-packages/flask_oauth2/resources/__init__.py", line 37, in decorated
    return f(*args, **kwargs)
  File "/usr/local/lib/python2.7/dist-packages/flask_permissions/permissions/__init__.py", line 57, in decorated
    return f(*args, **kwargs)
  File "/home/quynt13/Desktop/ACBank/agentstats-api/app/api/account.py", line 35, in list_accounts
    args = parser.parse(params)
  File "/usr/local/lib/python2.7/dist-packages/webargs/core.py", line 363, in parse
    self._on_validation_error(error)
  File "/usr/local/lib/python2.7/dist-packages/webargs/core.py", line 310, in _on_validation_error
    self.handle_error(error)
  File "/usr/local/lib/python2.7/dist-packages/webargs/flaskparser.py", line 105, in handle_error
    abort(status_code, messages=error.messages, exc=error)
  File "/usr/local/lib/python2.7/dist-packages/webargs/flaskparser.py", line 40, in abort
    raise err
UnprocessableEntity: 422 Unprocessable Entity: {'message': 'Validation error, re-check your data.', 'code': 422}
2017-11-10 08:58:08,442 ERROR: HTTP_STATUS_CODE_422: {'message': 'Validation error, re-check your data.', 'code': 422} [in /home/quynt13/Desktop/ACBank/agentstats-api/app/exceptions.py:191]
Traceback (most recent call last):
  File "/usr/local/lib/python2.7/dist-packages/flask/app.py", line 1612, in full_dispatch_request
    rv = self.dispatch_request()
  File "/usr/local/lib/python2.7/dist-packages/flask/app.py", line 1598, in dispatch_request
    return self.view_functions[rule.endpoint](**req.view_args)
  File "/usr/local/lib/python2.7/dist-packages/flask_oauth2/resources/__init__.py", line 37, in decorated
    return f(*args, **kwargs)
  File "/usr/local/lib/python2.7/dist-packages/flask_permissions/permissions/__init__.py", line 57, in decorated
    return f(*args, **kwargs)
  File "/home/quynt13/Desktop/ACBank/agentstats-api/app/api/minion.py", line 39, in list_minions
    args = parser.parse(params)
  File "/usr/local/lib/python2.7/dist-packages/webargs/core.py", line 363, in parse
    self._on_validation_error(error)
  File "/usr/local/lib/python2.7/dist-packages/webargs/core.py", line 310, in _on_validation_error
    self.handle_error(error)
  File "/usr/local/lib/python2.7/dist-packages/webargs/flaskparser.py", line 105, in handle_error
    abort(status_code, messages=error.messages, exc=error)
  File "/usr/local/lib/python2.7/dist-packages/webargs/flaskparser.py", line 40, in abort
    raise err
UnprocessableEntity: 422 Unprocessable Entity: {'message': 'Validation error, re-check your data.', 'code': 422}
2017-11-10 08:58:11,701 ERROR: HTTP_STATUS_CODE_422: {'message': 'Validation error, re-check your data.', 'code': 422} [in /home/quynt13/Desktop/ACBank/agentstats-api/app/exceptions.py:191]
Traceback (most recent call last):
  File "/usr/local/lib/python2.7/dist-packages/flask/app.py", line 1612, in full_dispatch_request
    rv = self.dispatch_request()
  File "/usr/local/lib/python2.7/dist-packages/flask/app.py", line 1598, in dispatch_request
    return self.view_functions[rule.endpoint](**req.view_args)
  File "/usr/local/lib/python2.7/dist-packages/flask_oauth2/resources/__init__.py", line 37, in decorated
    return f(*args, **kwargs)
  File "/usr/local/lib/python2.7/dist-packages/flask_permissions/permissions/__init__.py", line 57, in decorated
    return f(*args, **kwargs)
  File "/home/quynt13/Desktop/ACBank/agentstats-api/app/api/minion.py", line 39, in list_minions
    args = parser.parse(params)
  File "/usr/local/lib/python2.7/dist-packages/webargs/core.py", line 363, in parse
    self._on_validation_error(error)
  File "/usr/local/lib/python2.7/dist-packages/webargs/core.py", line 310, in _on_validation_error
    self.handle_error(error)
  File "/usr/local/lib/python2.7/dist-packages/webargs/flaskparser.py", line 105, in handle_error
    abort(status_code, messages=error.messages, exc=error)
  File "/usr/local/lib/python2.7/dist-packages/webargs/flaskparser.py", line 40, in abort
    raise err
UnprocessableEntity: 422 Unprocessable Entity: {'message': 'Validation error, re-check your data.', 'code': 422}
2017-11-12 22:39:36,662 INFO: Config filename: app/config.py [in /home/quynt13/Desktop/ACBank/agentstats-api/app/app.py:109]
2017-11-12 22:39:36,684 INFO: App log folder: /home/quynt13/Desktop/ACBank/agentstats-api/logs [in /home/quynt13/Desktop/ACBank/agentstats-api/app/app.py:110]
